Workbook

Sheet PRECIOS ACUM
B1: PRECIOS ESTIMADOS DE ENERGIA y POTENCIA x MERCADO
B2: Incluye CVP y estimación de renta marginal en base a datos operativos
B3: Incluye estimación de costos variables y fijos de la generación asignada | Q3: 45962
B4: No incluye costos de servicios adicionales ni de transporte en AT/DT | Q4: 45992
B5: No incluye contratos MATE - MATP a ser transaccionados | F5: =+IF(MONTH(D7)=MONTH(MAX('Mono SPOT MAT'!G19:G1048576)),"Análisis hasta:","") -> Análisis hasta: | G5: =+IF(MONTH(D7)=MONTH(MAX('Mono SPOT MAT'!G19:G1048576)),MAX('Mono SPOT MAT'!G19:G1048576),"") -> 46195 | Q5: 46023
B6: Datos provisorios a confirmar con la salida del DTE | F6: Días del mes: | G6: =+EDATE(D7,1)-D7 -> 30 | Q6: 46054
B7: VALORES ACUMULADO MES | D7: 46174 | Q7: 46082
B8: Mercado asociado a Grandes Usuarios y demanda | F8: Mercado asociado a demanda estacionalizada | Q8: 46113
B9: estacionalizada no cubierta por la generación asignada | F9: (Res/NO Res) cubierta por la generación asignada | Q9: 46143
D10: MERCADO SPOT | H10: MERCADO ASIGNADA | Q10: 46174
A11: =+A10+1 -> 1 | B11: POT MEDIA | C11: MW med | D11: =+VLOOKUP($D$7,'Fisico SPOT MAT'!$G$7:$M$16,7,FALSE) -> 6350.6732 | F11: POT MEDIA | G11: MW med | H11: =+VLOOKUP($D$7,'Fisico ASIG'!$E$8:$W$16,10,FALSE) -> 9215.3935
A12: =+A11+1 -> 2 | B12: CMg | C12: usd/MWh | D12: =+VLOOKUP($D$7,Precios!$D$6:$N$14,2,FALSE) -> 204.28822
A13: =+A12+1 -> 3 | B13: ENERGIA | C13: usd/MWh | D13: =+VLOOKUP($D$7,Precios!$D$6:$N$14,3,FALSE) -> 156.78839 | F13: ENERGIA | G13: usd/MWh | H13: =+VLOOKUP($D$7,Precios!$D$6:$N$14,6,FALSE) -> 80.427532
A14: =+A13+1 -> 4 | B14: POTENCIA | C14: usd/MWhrp | D14: =+VLOOKUP($D$7,Precios!$D$6:$N$14,4,FALSE) -> 17.6 | F14: POTENCIA | G14: usd/MWhrp | H14: =+VLOOKUP($D$7,Precios!$D$6:$N$14,7,FALSE) -> 17.6
A15: =+A14+1 -> 5 | B15: MONO E + P para FC | C15: usd/MWh | D15: =+VLOOKUP($D$7,Precios!$D$6:$AC$14,18,FALSE) -> 167.95362 | F15: MONO ASIG | G15: usd/MWh | H15: =+VLOOKUP($D$7,Precios!$D$6:$N$14,5,FALSE) -> 95.202871
B16: Servicios | C16: usd/MWh | F16: =+B16 -> Servicios | G16: usd/MWh
B17: Transporte | C17: usd/MWh | F17: =+B17 -> Transporte | G17: usd/MWh
B18: MONO E + P para FC | C18: usd/MWh | D18: =+D15+D16+D17 -> 167.95362 | F18: MONO ASIG | G18: usd/MWh | H18: =+H15+H16+H17 -> 95.202871
F20: Mercado a término de Energía
F21: Generación Térmica asociada al MAT
D22: TÉRMICO SPOT | H22: TÉRMICO MATE
B23: POT MEDIA | C23: MW med | D23: =+VLOOKUP($D$7,'Fisico SPOT MAT'!$G$7:$Z$16,2,FALSE) -> 5811.3069 | F23: POT MEDIA | G23: MW med | H23: =+VLOOKUP($D$7,'Fisico SPOT MAT'!$G$7:$Z$16,14,FALSE) -> 700
B24: ENERGIA | C24: usd/MWh | D24: =+VLOOKUP($D$7,'Mono SPOT MAT'!$G$7:$M$15,2,FALSE) -> 161.3501 | F24: ENERGIA | G24: usd/MWh | H24: =+VLOOKUP($D$7,Precios!$D$6:$N$14,8,FALSE) -> 75
B25: POTENCIA | C25: usd/MWhrp | D25: =+VLOOKUP($D$7,Precios!$D$6:$N$14,4,FALSE) -> 17.6 | F25: POTENCIA | G25: usd/MWhrp | H25: =+IF(H23=0,0,VLOOKUP($D$7,Precios!$D$6:$N$14,7,FALSE)) -> 17.6
B26: MONO E + P para FC | C26: usd/MWh | D26: =+VLOOKUP($D$7,Precios!$D$6:$AC$14,19,FALSE) -> 172.51533 | F26: MONO MAT | G26: usd/MWh | H26: =+IF(H23=0,0,+D26-D24+H24) -> 86.165235
A30: =+A21+1 -> 1 | B30: Potencia Media de generación spot en el período | E30: =+E21+1 -> 1 | F30: Potencia Media de generación asignada en el período
A31: =+A30+1 -> 2 | B31: Costo Marginal Medio
A32: =+A31+1 -> 3 | B32: Precio de la Energía en el Mercado Spot | E32: 3 | F32: Precio de la Energía mensual para el Mercado de Asignada
A33: =+A32+1 -> 4 | B33: Precio de la Potencia en el Mercado Spot | E33: =+E32+1 -> 4 | F33: Precio de la Potencia para el Mercado de Asignada
A34: =+A33+1 -> 5 | B34: Valor monómico simulado Mercado Spot para FC y HRP | E34: 5 | F34: Monómico de Costo de la Generación Asignada

Sheet Precios
B1: PRECIOS ESTIMADOS DE ENERGIA y POTENCIA x MERCADO
B2: Incluye CVP y estimación de renta marginal en base a datos operativos
B3: Incluye estimación de costos variables y fijos de la generación asignada
B5: VALORES ECONOMICOS - ACUMULADO MES | E5: usd/MWh | F5: usd/MWh | G5: usd/MWhrp | H5: usd/MWh | I5: usd/MWh | J5: usd/MWhrp | K5: usd/MWh | T5: usd/MWh | U5: usd/MWh | X5: usd/MWh
C6: Cant días: | D6: MES | E6: CMg | F6: ENER SPOT | G6: POT SPOT | H6: MONO ASIG | I6: ENER ASIG | J6: POT ASIG | K6: TÉRMICO MATE | N6: POT SPOT | P6: HRP | Q6: HMES | R6: Factor Potencia | S6: FC SPOT | T6: POT SPOT | U6: MONO SPOT | V6: TÉRMICO SPOT | W6: FC Asignado | X6: POT asig
C7: =+EDATE(D7,1)-D7 -> 30 | D7: 45962 | E7: =AVERAGEIFS($E$20:$E$1048576,$B$20:$B$1048576,D7) -> 32.334184 | F7: =+SUMPRODUCT(F51:F80,'Fisico SPOT MAT'!M51:M80)/SUM('Fisico SPOT MAT'!M51:M80) -> 35.782032 | G7: =+SUMPRODUCT(G51:G80,'Fisico SPOT MAT'!S51:S80)/SUM('Fisico SPOT MAT'!S51:S80) -> 14.4 | H7: =+SUMPRODUCT(H51:H80,'Fisico SPOT MAT'!$P$51:$P$80)/SUM('Fisico SPOT MAT'!$P$51:$P$80) -> 62.201004 | I7: =+SUMPRODUCT(I51:I80,'Fisico SPOT MAT'!$P$51:$P$80)/SUM('Fisico SPOT MAT'!$P$51:$P$80) -> 47.78583 | J7: =+SUMPRODUCT(J51:J80,'Fisico SPOT MAT'!$Y$51:$Y$80)/SUM('Fisico SPOT MAT'!$Y$51:$Y$80) -> 14.4 | N7: =AVERAGEIFS($N$20:$N$1048576,$B$20:$B$1048576,D7) -> 11.53116 | P7: ='Fisico SPOT MAT'!E8 -> 348 | Q7: =+C7*24 -> 720 | R7: =AVERAGEIFS(R$19:R$1048576,$B$19:$B$1048576,$D7) -> 0.9 | S7: 0.75 | T7: =+G7*P7/Q7/S7 -> 9.28 | U7: =+T7+F7 -> 45.062032 | V7: =+T7+'Mono SPOT MAT'!H8 -> 47.062843 | W7: 0.52 | X7: =+J7*P7/Q7/W7 -> 13.384615
C8: =+EDATE(D8,1)-D8 -> 31 | D8: 45992 | E8: =AVERAGEIFS($E$20:$E$1048576,$B$20:$B$1048576,D8) -> 40.553132 | F8: =+SUMPRODUCT(F81:F111,'Fisico SPOT MAT'!M81:M111)/SUM('Fisico SPOT MAT'!M81:M111) -> 40.399389 | G8: =+SUMPRODUCT(G81:G111,'Fisico SPOT MAT'!S81:S111)/SUM('Fisico SPOT MAT'!S81:S111) -> 17.6 | H8: =+SUMPRODUCT(H81:H111,'Fisico SPOT MAT'!$P$81:$P$111)/SUM('Fisico SPOT MAT'!$P$81:$P$111) -> 63.804977 | I8: =+SUMPRODUCT(I81:I111,'Fisico SPOT MAT'!$P$81:$P$111)/SUM('Fisico SPOT MAT'!$P$81:$P$111) -> 46.335994 | J8: =+SUMPRODUCT(J81:J111,'Fisico SPOT MAT'!$Y$81:$Y$111)/SUM('Fisico SPOT MAT'!$Y$81:$Y$111) -> 17.6 | N8: =AVERAGEIFS($N$20:$N$1048576,$B$20:$B$1048576,D8) -> 15.772536 | P8: ='Fisico SPOT MAT'!E9 -> 384 | Q8: =+C8*24 -> 744 | R8: =AVERAGEIFS(R$19:R$1048576,$B$19:$B$1048576,$D8) -> 1.1 | S8: 0.75 | T8: =+G8*P8/Q8/S8 -> 12.111828 | U8: =+T8+F8 -> 52.511217 | V8: =+T8+'Mono SPOT MAT'!H9 -> 54.271807 | W8: 0.52 | X8: =+J8*P8/Q8/W8 -> 17.468983
C9: =+EDATE(D9,1)-D9 -> 31 | D9: 46023 | E9: =AVERAGEIFS($E$20:$E$1048576,$B$20:$B$1048576,D9) -> 55.612597 | F9: =+SUMPRODUCT(F112:F142,'Fisico SPOT MAT'!M112:M142)/SUM('Fisico SPOT MAT'!M112:M142) -> 42.573442 | G9: =+SUMPRODUCT(G112:G142,'Fisico SPOT MAT'!S112:S142)/SUM('Fisico SPOT MAT'!S112:S142) -> 17.6 | H9: =+SUMPRODUCT(H112:H142,'Fisico SPOT MAT'!$P$112:$P$142)/SUM('Fisico SPOT MAT'!$P$112:$P$142) -> 65.972923 | I9: =+SUMPRODUCT(I112:I142,'Fisico SPOT MAT'!$P$112:$P$142)/SUM('Fisico SPOT MAT'!$P$112:$P$142) -> 48.412956 | J9: =+SUMPRODUCT(J112:J142,'Fisico SPOT MAT'!$Y$112:$Y$142)/SUM('Fisico SPOT MAT'!$Y$112:$Y$142) -> 17.6 | N9: =AVERAGEIFS($N$20:$N$1048576,$B$20:$B$1048576,D9) -> 15.674033 | P9: ='Fisico SPOT MAT'!E10 -> 386 | Q9: =+C9*24 -> 744 | R9: =AVERAGEIFS(R$19:R$1048576,$B$19:$B$1048576,$D9) -> 1.1 | S9: 0.75 | T9: =+G9*P9/Q9/S9 -> 12.17491 | U9: =+T9+F9 -> 54.748353 | V9: =+T9+'Mono SPOT MAT'!H10 -> 56.984422 | W9: 0.52 | X9: =+J9*P9/Q9/W9 -> 17.559967
C10: =+EDATE(D10,1)-D10 -> 28 | D10: 46054 | E10: =AVERAGEIFS($E$20:$E$1048576,$B$20:$B$1048576,D10) -> 52.514713 | F10: =+SUMPRODUCT(F143:F170,'Fisico SPOT MAT'!M143:M170)/SUM('Fisico SPOT MAT'!M143:M170) -> 42.909911 | G10: =+SUMPRODUCT(G143:G170,'Fisico SPOT MAT'!S143:S170)/SUM('Fisico SPOT MAT'!S143:S170) -> 17.6 | H10: =+SUMPRODUCT(H143:H170,'Fisico ASIG'!$N$143:$N$170)/SUM('Fisico ASIG'!$N$143:$N$170) -> 73.131269 | I10: =+SUMPRODUCT(I143:I170,'Fisico ASIG'!$N$143:$N$170)/SUM('Fisico ASIG'!$N$143:$N$170) -> 56.208193 | J10: =+SUMPRODUCT(J143:J170,'Fisico ASIG'!$W$143:$W$170)/SUM('Fisico ASIG'!$W$143:$W$170) -> 17.6 | N10: =AVERAGEIFS($N$20:$N$1048576,$B$20:$B$1048576,D10) -> 15.854857 | P10: ='Fisico SPOT MAT'!E11 -> 336 | Q10: =+C10*24 -> 672 | R10: =AVERAGEIFS(R$19:R$1048576,$B$19:$B$1048576,$D10) -> 1.1 | S10: 0.75 | T10: =+G10*P10/Q10/S10 -> 11.733333 | U10: =+T10+F10 -> 54.643244 | V10: =+T10+'Mono SPOT MAT'!H11 -> 57.10384 | W10: 0.52 | X10: =+J10*P10/Q10/W10 -> 16.923077
C11: =+EDATE(D11,1)-D11 -> 31 | D11: 46082 | E11: =AVERAGEIFS($E$20:$E$1048576,$B$20:$B$1048576,D11) -> 62.286214 | F11: =+SUMPRODUCT(F171:F201,'Fisico SPOT MAT'!M171:M201)/SUM('Fisico SPOT MAT'!M171:M201) -> 45.274491 | G11: =+SUMPRODUCT(G171:G201,'Fisico SPOT MAT'!S171:S201)/SUM('Fisico SPOT MAT'!S171:S201) -> 14.4 | H11: =+SUMPRODUCT(H171:H201,'Fisico ASIG'!$N$171:$N$201)/SUM('Fisico ASIG'!$N$171:$N$201) -> 71.173352 | I11: =+SUMPRODUCT(I171:I201,'Fisico ASIG'!$N$171:$N$201)/SUM('Fisico ASIG'!$N$171:$N$201) -> 58.680851 | J11: =+SUMPRODUCT(J171:J201,'Fisico ASIG'!W$171:W$201)/SUM('Fisico ASIG'!W$171:W$201) -> 14.4 | N11: =AVERAGEIFS($N$20:$N$1048576,$B$20:$B$1048576,D11) -> 15.212011 | P11: ='Fisico SPOT MAT'!E12 -> 374 | Q11: =+C11*24 -> 744 | R11: =AVERAGEIFS(R$19:R$1048576,$B$19:$B$1048576,$D11) -> 0.9 | S11: 0.82756876 | T11: =+G11*P11/Q11/S11 -> 8.7469586 | U11: =+T11+F11 -> 54.021449 | V11: =+T11+'Mono SPOT MAT'!H12 -> 55.751221 | W11: 0.5794444 | X11: =+J11*P11/Q11/W11 -> 12.492501
C12: =+'Mono SPOT MAT'!F13 -> 30 | D12: 46113 | E12: =AVERAGEIFS($E$20:$E$1048576,$B$20:$B$1048576,D12) -> 86.168556 | F12: =+SUMPRODUCT(F202:F231,'Fisico SPOT MAT'!M202:M231)/SUM('Fisico SPOT MAT'!M202:M231) -> 50.818294 | G12: =+SUMPRODUCT(G202:G231,'Fisico SPOT MAT'!S202:S231)/SUM('Fisico SPOT MAT'!S202:S231) -> 14.4 | H12: =+SUMPRODUCT(H202:H231,'Fisico ASIG'!$N$202:$N$231)/SUM('Fisico ASIG'!$N$202:$N$231) -> 72.749403 | I12: =+SUMPRODUCT(I202:I231,'Fisico ASIG'!$N$202:$N$231)/SUM('Fisico ASIG'!$N$202:$N$231) -> 60.683829 | J12: =+SUMPRODUCT(J202:J231,'Fisico ASIG'!W$202:W$231)/SUM('Fisico ASIG'!W$202:W$231) -> 14.4 | N12: =AVERAGEIFS($N$20:$N$1048576,$B$20:$B$1048576,D12) -> 15.093951 | P12: 368 | Q12: =30*24 -> 720 | R12: =AVERAGEIFS(R$19:R$1048576,$B$19:$B$1048576,$D12) -> 0.9 | S12: 0.82756876 | T12: =+G12*P12/Q12/S12 -> 8.8935208 | U12: =+T12+F12 -> 59.711815 | V12: =+T12+'Mono SPOT MAT'!H13 -> 63.092365 | W12: 0.61 | X12: =+J12*P12/Q12/W12 -> 12.065574
C13: =+'Mono SPOT MAT'!F14 -> 31 | D13: 46143 | E13: =AVERAGEIFS($E$20:$E$1048576,$B$20:$B$1048576,D13) -> 188.32262 | F13: =+SUMPRODUCT(F232:F262,'Fisico SPOT MAT'!M232:M262)/SUM('Fisico SPOT MAT'!M232:M262) -> 115.34849 | G13: =+SUMPRODUCT(G232:G262,'Fisico SPOT MAT'!S232:S262)/SUM('Fisico SPOT MAT'!S232:S262) -> 14.4 | H13: =+SUMPRODUCT(H232:H262,'Fisico ASIG'!$N$232:$N$262)/SUM('Fisico ASIG'!$N$232:$N$262) -> 85.536663 | I13: =+SUMPRODUCT(I232:I262,'Fisico ASIG'!$N$232:$N$262)/SUM('Fisico ASIG'!$N$232:$N$262) -> 73.471089 | J13: =+SUMPRODUCT(J232:J262,'Fisico ASIG'!W$232:W$262)/SUM('Fisico ASIG'!W$232:W$262) -> 14.4 | K13: =+SUMPRODUCT(K232:K262,'Fisico SPOT MAT'!T232:T262)/SUM('Fisico SPOT MAT'!T232:T262) -> 75 | N13: =AVERAGEIFS($N$20:$N$1048576,$B$20:$B$1048576,D13) -> 15.324438 | P13: 362 | Q13: =31*24 -> 744 | R13: =AVERAGEIFS(R$19:R$1048576,$B$19:$B$1048576,$D13) -> 0.9 | S13: 0.82756876 | T13: =+G13*P13/Q13/S13 -> 8.4663075 | U13: =+T13+F13 -> 123.81479 | V13: =+T13+'Mono SPOT MAT'!H14 -> 122.59214 | W13: 0.61 | X13: =+J13*P13/Q13/W13 -> 11.485986
B14: =+'Mono SPOT MAT'!E15 -> días en análisis: | C14: =+'Mono SPOT MAT'!F15 -> 22 | D14: 46174 | E14: =AVERAGEIFS($E$20:$E$1048576,$B$20:$B$1048576,D14) -> 204.28822 | F14: =+SUMPRODUCT(F263:F284,'Fisico SPOT MAT'!M263:M284)/SUM('Fisico SPOT MAT'!M263:M284) -> 156.78839 | G14: =+SUMPRODUCT(G263:G284,'Fisico SPOT MAT'!N263:N284)/SUM('Fisico SPOT MAT'!N263:N284) -> 17.6 | H14: =+SUMPRODUCT(H263:H284,'Fisico SPOT MAT'!O263:O284)/SUM('Fisico SPOT MAT'!O263:O284) -> 95.202871 | I14: =+SUMPRODUCT(I263:I284,'Fisico SPOT MAT'!P263:P284)/SUM('Fisico SPOT MAT'!P263:P284) -> 80.427532 | J14: =+SUMPRODUCT(J263:J284,'Fisico SPOT MAT'!Q263:Q284)/SUM('Fisico SPOT MAT'!Q263:Q284) -> 17.6 | K14: =+SUMPRODUCT(K263:K284,'Fisico SPOT MAT'!T263:T284)/SUM('Fisico SPOT MAT'!T263:T284) -> 75 | N14: =AVERAGEIFS($N$20:$N$1048576,$B$20:$B$1048576,D14) -> 15.728859 | P14: 378 | Q14: =30*24 -> 720 | R14: =AVERAGEIFS(R$19:R$1048576,$B$19:$B$1048576,$D14) -> 1.1 | S14: 0.82756876 | T14: =+G14*P14/Q14/S14 -> 11.165235 | U14: =+T14+F14 -> 167.95362 | V14: =+T14+'Mono SPOT MAT'!H15 -> 172.51533 | W14: 0.61 | X14: =+J14*P14/Q14/W14 -> 15.147541
B17: VALORES FISICOS - PASO DIARIO
E18: usd/MWh | F18: usd/MWh | G18: usd/MWhrp | H18: usd/MWh | I18: usd/MWh | J18: usd/MWhrp | K18: usd/MWh
A19: AÑO | B19: MES | C19: TIPO dia | D19: DIA | E19: CMg | F19: ENER SPOT | G19: POT SPOT | H19: MONO ASIG | I19: ENER ASIG | J19: POT ASIG | K19: ENER TERM MAT | N19: POT SPOT | R19: Factor Potencia | Y19: =$D19 -> DIA | Z19: =+E19 -> CMg | AA19: CVP | AB19: RMA
A20: =YEAR(D20) -> 2025 | B20: =DATE(A20,MONTH(D20),1) -> 45931 | C20: mié. | D20: 45931 | E20: 24.854148 | F20: =+'Mono SPOT MAT'!M20/'Fisico SPOT MAT'!M20/24 -> 29.684186 | G20: =16*R20 -> 14.4 | H20: =+'Mono ASIG'!AA20 -> 61.946815 | I20: =+H20-J20*380/730/0.52 -> 47.531641 | J20: =16*R20 -> 14.4 | K20: =+'Mono SPOT MAT'!T20 -> 0 | N20: =+'Mono SPOT MAT'!S20/'Fisico SPOT MAT'!S20/'Fisico SPOT MAT'!E20 -> 11.3809 | R20: 0.9
A21: =YEAR(D21) -> 2025 | B21: =DATE(A21,MONTH(D21),1) -> 45931 | C21: jue. | D21: =+ D20+1 -> 45932 | E21: 27.983237 | F21: =+'Mono SPOT MAT'!M21/'Fisico SPOT MAT'!M21/24 -> 30.044257 | G21: =16*R21 -> 14.4 | H21: =+'Mono ASIG'!AA21 -> 60.116829 | I21: =+H21-J21*380/730/0.52 -> 45.701655 | J21: =16*R21 -> 14.4 | K21: =+'Mono SPOT MAT'!T21 -> 0 | N21: =+'Mono SPOT MAT'!S21/'Fisico SPOT MAT'!S21/'Fisico SPOT MAT'!E21 -> 11.407825 | R21: 0.9
A22: =YEAR(D22) -> 2025 | B22: =DATE(A22,MONTH(D22),1) -> 45931 | C22: vie. | D22: =+ D21+1 -> 45933 | E22: 27.892877 | F22: =+'Mono SPOT MAT'!M22/'Fisico SPOT MAT'!M22/24 -> 30.691543 | G22: =16*R22 -> 14.4 | H22: =+'Mono ASIG'!AA22 -> 58.649 | I22: =+H22-J22*380/730/0.52 -> 44.233826 | J22: =16*R22 -> 14.4 | K22: =+'Mono SPOT MAT'!T22 -> 0 | N22: =+'Mono SPOT MAT'!S22/'Fisico SPOT MAT'!S22/'Fisico SPOT MAT'!E22 -> 11.413798 | R22: 0.9
A23: =YEAR(D23) -> 2025 | B23: =DATE(A23,MONTH(D23),1) -> 45931 | C23: sáb. | D23: =+ D22+1 -> 45934 | E23: 31.530274 | F23: =+'Mono SPOT MAT'!M23/'Fisico SPOT MAT'!M23/24 -> 32.022819 | G23: =16*R23 -> 14.4 | H23: =+'Mono ASIG'!AA23 -> 61.22392 | I23: =+H23-J23*380/730/0.52 -> 46.808746 | J23: =16*R23 -> 14.4 | K23: =+'Mono SPOT MAT'!T23 -> 0 | N23: =+'Mono SPOT MAT'!S23/'Fisico SPOT MAT'!S23/'Fisico SPOT MAT'!E23 -> 11.377526 | R23: 0.9
A24: =YEAR(D24) -> 2025 | B24: =DATE(A24,MONTH(D24),1) -> 45931 | C24: dom. | D24: =+ D23+1 -> 45935 | E24: 28.785433 | F24: =+'Mono SPOT MAT'!M24/'Fisico SPOT MAT'!M24/24 -> 31.941739 | G24: =16*R24 -> 14.4 | H24: =+'Mono ASIG'!AA24 -> 63.180646 | I24: =+H24-J24*380/730/0.52 -> 48.765472 | J24: =16*R24 -> 14.4 | K24: =+'Mono SPOT MAT'!T24 -> 0 | N24: =+'Mono SPOT MAT'!S24/'Fisico SPOT MAT'!S24/'Fisico SPOT MAT'!E24 -> 11.37484 | R24: 0.9
A25: =YEAR(D25) -> 2025 | B25: =DATE(A25,MONTH(D25),1) -> 45931 | C25: lun. | D25: =+ D24+1 -> 45936 | E25: 31.612932 | F25: =+'Mono SPOT MAT'!M25/'Fisico SPOT MAT'!M25/24 -> 30.996048 | G25: =16*R25 -> 14.4 | H25: =+'Mono ASIG'!AA25 -> 61.080366 | I25: =+H25-J25*380/730/0.52 -> 46.665192 | J25: =16*R25 -> 14.4 | K25: =+'Mono SPOT MAT'!T25 -> 0 | N25: =+'Mono SPOT MAT'!S25/'Fisico SPOT MAT'!S25/'Fisico SPOT MAT'!E25 -> 11.380223 | R25: 0.9
A26: =YEAR(D26) -> 2025 | B26: =DATE(A26,MONTH(D26),1) -> 45931 | C26: mar. | D26: =+ D25+1 -> 45937 | E26: 31.570178 | F26: =+'Mono SPOT MAT'!M26/'Fisico SPOT MAT'!M26/24 -> 30.784964 | G26: =16*R26 -> 14.4 | H26: =+'Mono ASIG'!AA26 -> 63.155935 | I26: =+H26-J26*380/730/0.52 -> 48.740761 | J26: =16*R26 -> 14.4 | K26: =+'Mono SPOT MAT'!T26 -> 0 | N26: =+'Mono SPOT MAT'!S26/'Fisico SPOT MAT'!S26/'Fisico SPOT MAT'!E26 -> 11.376157 | R26: 0.9
A27: =YEAR(D27) -> 2025 | B27: =DATE(A27,MONTH(D27),1) -> 45931 | C27: mié. | D27: =+ D26+1 -> 45938 | E27: 27.96837 | F27: =+'Mono SPOT MAT'!M27/'Fisico SPOT MAT'!M27/24 -> 31.348177 | G27: =16*R27 -> 14.4 | H27: =+'Mono ASIG'!AA27 -> 65.376973 | I27: =+H27-J27*380/730/0.52 -> 50.961799 | J27: =16*R27 -> 14.4 | K27: =+'Mono SPOT MAT'!T27 -> 0 | N27: =+'Mono SPOT MAT'!S27/'Fisico SPOT MAT'!S27/'Fisico SPOT MAT'!E27 -> 11.379375 | R27: 0.9
A28: =YEAR(D28) -> 2025 | B28: =DATE(A28,MONTH(D28),1) -> 45931 | C28: jue. | D28: =+ D27+1 -> 45939 | E28: 29.918786 | F28: =+'Mono SPOT MAT'!M28/'Fisico SPOT MAT'!M28/24 -> 30.859801 | G28: =16*R28 -> 14.4 | H28: =+'Mono ASIG'!AA28 -> 63.346287 | I28: =+H28-J28*380/730/0.52 -> 48.931114 | J28: =16*R28 -> 14.4 | K28: =+'Mono SPOT MAT'!T28 -> 0 | N28: =+'Mono SPOT MAT'!S28/'Fisico SPOT MAT'!S28/'Fisico SPOT MAT'!E28 -> 11.37513 | R28: 0.9
A29: =YEAR(D29) -> 2025 | B29: =DATE(A29,MONTH(D29),1) -> 45931 | C29: vie. | D29: =+ D28+1 -> 45940 | E29: 28.943681 | F29: =+'Mono SPOT MAT'!M29/'Fisico SPOT MAT'!M29/24 -> 31.651831 | G29: =16*R29 -> 14.4 | H29: =+'Mono ASIG'!AA29 -> 63.163796 | I29: =+H29-J29*380/730/0.52 -> 48.748622 | J29: =16*R29 -> 14.4 | K29: =+'Mono SPOT MAT'!T29 -> 0 | N29: =+'Mono SPOT MAT'!S29/'Fisico SPOT MAT'!S29/'Fisico SPOT MAT'!E29 -> 11.374467 | R29: 0.9
A30: =YEAR(D30) -> 2025 | B30: =DATE(A30,MONTH(D30),1) -> 45931 | C30: sáb. | D30: =+ D29+1 -> 45941 | E30: 30.423262 | F30: =+'Mono SPOT MAT'!M30/'Fisico SPOT MAT'!M30/24 -> 31.926912 | G30: =16*R30 -> 14.4 | H30: =+'Mono ASIG'!AA30 -> 62.649776 | I30: =+H30-J30*380/730/0.52 -> 48.234602 | J30: =16*R30 -> 14.4 | K30: =+'Mono SPOT MAT'!T30 -> 0 | N30: =+'Mono SPOT MAT'!S30/'Fisico SPOT MAT'!S30/'Fisico SPOT MAT'!E30 -> 11.373415 | R30: 0.9
A31: =YEAR(D31) -> 2025 | B31: =DATE(A31,MONTH(D31),1) -> 45931 | C31: dom. | D31: =+ D30+1 -> 45942 | E31: 19.247504 | F31: =+'Mono SPOT MAT'!M31/'Fisico SPOT MAT'!M31/24 -> 32.592034 | G31: =16*R31 -> 14.4 | H31: =+'Mono ASIG'!AA31 -> 68.841525 | I31: =+H31-J31*380/730/0.52 -> 54.426351 | J31: =16*R31 -> 14.4 | K31: =+'Mono SPOT MAT'!T31 -> 0 | N31: =+'Mono SPOT MAT'!S31/'Fisico SPOT MAT'!S31/'Fisico SPOT MAT'!E31 -> 11.366155 | R31: 0.9
A32: =YEAR(D32) -> 2025 | B32: =DATE(A32,MONTH(D32),1) -> 45931 | C32: lun. | D32: =+ D31+1 -> 45943 | E32: 28.342066 | F32: =+'Mono SPOT MAT'!M32/'Fisico SPOT MAT'!M32/24 -> 31.780016 | G32: =16*R32 -> 14.4 | H32: =+'Mono ASIG'!AA32 -> 61.633753 | I32: =+H32-J32*380/730/0.52 -> 47.218579 | J32: =16*R32 -> 14.4 | K32: =+'Mono SPOT MAT'!T32 -> 0 | N32: =+'Mono SPOT MAT'!S32/'Fisico SPOT MAT'!S32/'Fisico SPOT MAT'!E32 -> 11.369995 | R32: 0.9
... A80: =YEAR(D80) -> 2025 | B80: =DATE(A80,MONTH(D80),1) -> 45962 | C80: dom | D80: =+ D79+1 -> 45991 | E80: 37.418409 | F80: =+'Mono SPOT MAT'!M80/'Fisico SPOT MAT'!M80/24 -> 35.166272 | G80: =16*R80 -> 14.4 | H80: =+'Mono ASIG'!AA80 -> 71.721664 | I80: =+H80-J80*380/730/0.52 -> 57.30649 | J80: =16*R80 -> 14.4 | K80: =+'Mono SPOT MAT'!T80 -> 0 | N80: =+'Mono SPOT MAT'!S80/'Fisico SPOT MAT'!S80/'Fisico SPOT MAT'!E80 -> 11.571719 | R80: 0.9
A81: =YEAR(D81) -> 2025 | B81: =DATE(A81,MONTH(D81),1) -> 45992 | C81: lun | D81: =+ D80+1 -> 45992 | E81: 47.852748 | F81: =+'Mono SPOT MAT'!M81/'Fisico SPOT MAT'!M81/24 -> 39.212751 | G81: =16*R81 -> 17.6 | H81: =+'Mono ASIG'!AA81 -> 64.022508 | I81: =+H81-J81*384/744/0.52 -> 46.553526 | J81: =16*R81 -> 17.6 | K81: =+'Mono SPOT MAT'!T81 -> 0 | N81: =+'Mono SPOT MAT'!S81/'Fisico SPOT MAT'!S81/'Fisico SPOT MAT'!E81 -> 15.791563 | R81: 1.1
A82: =YEAR(D82) -> 2025 | B82: =DATE(A82,MONTH(D82),1) -> 45992 | C82: mar | D82: =+ D81+1 -> 45993 | E82: 44.491079 | F82: =+'Mono SPOT MAT'!M82/'Fisico SPOT MAT'!M82/24 -> 38.655333 | G82: =16*R82 -> 17.6 | H82: =+'Mono ASIG'!AA82 -> 65.403461 | I82: =+H82-J82*384/744/0.52 -> 47.934479 | J82: =16*R82 -> 17.6 | K82: =+'Mono SPOT MAT'!T82 -> 0 | N82: =+'Mono SPOT MAT'!S82/'Fisico SPOT MAT'!S82/'Fisico SPOT MAT'!E82 -> 15.717185 | R82: 1.1
A83: =YEAR(D83) -> 2025 | B83: =DATE(A83,MONTH(D83),1) -> 45992 | C83: mié | D83: =+ D82+1 -> 45994 | E83: 49.450391 | F83: =+'Mono SPOT MAT'!M83/'Fisico SPOT MAT'!M83/24 -> 40.563123 | G83: =16*R83 -> 17.6 | H83: =+'Mono ASIG'!AA83 -> 60.136069 | I83: =+H83-J83*384/744/0.52 -> 42.667086 | J83: =16*R83 -> 17.6 | K83: =+'Mono SPOT MAT'!T83 -> 0 | N83: =+'Mono SPOT MAT'!S83/'Fisico SPOT MAT'!S83/'Fisico SPOT MAT'!E83 -> 15.603869 | R83: 1.1
A84: =YEAR(D84) -> 2025 | B84: =DATE(A84,MONTH(D84),1) -> 45992 | C84: jue | D84: =+ D83+1 -> 45995 | E84: 48.991631 | F84: =+'Mono SPOT MAT'!M84/'Fisico SPOT MAT'!M84/24 -> 41.329226 | G84: =16*R84 -> 17.6 | H84: =+'Mono ASIG'!AA84 -> 58.429944 | I84: =+H84-J84*384/744/0.52 -> 40.960961 | J84: =16*R84 -> 17.6 | K84: =+'Mono SPOT MAT'!T84 -> 0 | N84: =+'Mono SPOT MAT'!S84/'Fisico SPOT MAT'!S84/'Fisico SPOT MAT'!E84 -> 15.598166 | R84: 1.1
A85: =YEAR(D85) -> 2025 | B85: =DATE(A85,MONTH(D85),1) -> 45992 | C85: vie | D85: =+ D84+1 -> 45996 | E85: 46.55726 | F85: =+'Mono SPOT MAT'!M85/'Fisico SPOT MAT'!M85/24 -> 41.49849 | G85: =16*R85 -> 17.6 | H85: =+'Mono ASIG'!AA85 -> 57.10996 | I85: =+H85-J85*384/744/0.52 -> 39.640978 | J85: =16*R85 -> 17.6 | K85: =+'Mono SPOT MAT'!T85 -> 0 | N85: =+'Mono SPOT MAT'!S85/'Fisico SPOT MAT'!S85/'Fisico SPOT MAT'!E85 -> 15.745533 | R85: 1.1
A86: =YEAR(D86) -> 2025 | B86: =DATE(A86,MONTH(D86),1) -> 45992 | C86: sáb | D86: =+ D85+1 -> 45997 | E86: 59.777719 | F86: =+'Mono SPOT MAT'!M86/'Fisico SPOT MAT'!M86/24 -> 45.074175 | G86: =16*R86 -> 17.6 | H86: =+'Mono ASIG'!AA86 -> 61.338369 | I86: =+H86-J86*384/744/0.52 -> 43.869387 | J86: =16*R86 -> 17.6 | K86: =+'Mono SPOT MAT'!T86 -> 0 | N86: =+'Mono SPOT MAT'!S86/'Fisico SPOT MAT'!S86/'Fisico SPOT MAT'!E86 -> 15.666099 | R86: 1.1
A87: =YEAR(D87) -> 2025 | B87: =DATE(A87,MONTH(D87),1) -> 45992 | C87: dom | D87: =+ D86+1 -> 45998 | E87: 59.788687 | F87: =+'Mono SPOT MAT'!M87/'Fisico SPOT MAT'!M87/24 -> 44.279852 | G87: =16*R87 -> 17.6 | H87: =+'Mono ASIG'!AA87 -> 65.415919 | I87: =+H87-J87*384/744/0.52 -> 47.946937 | J87: =16*R87 -> 17.6 | K87: =+'Mono SPOT MAT'!T87 -> 0 | N87: =+'Mono SPOT MAT'!S87/'Fisico SPOT MAT'!S87/'Fisico SPOT MAT'!E87 -> 15.759381 | R87: 1.1
A88: =YEAR(D88) -> 2025 | B88: =DATE(A88,MONTH(D88),1) -> 45992 | C88: lun | D88: =+ D87+1 -> 45999 | E88: 33.099054 | F88: =+'Mono SPOT MAT'!M88/'Fisico SPOT MAT'!M88/24 -> 39.03201 | G88: =16*R88 -> 17.6 | H88: =+'Mono ASIG'!AA88 -> 69.521917 | I88: =+H88-J88*384/744/0.52 -> 52.052934 | J88: =16*R88 -> 17.6 | K88: =+'Mono SPOT MAT'!T88 -> 0 | N88: =+'Mono SPOT MAT'!S88/'Fisico SPOT MAT'!S88/'Fisico SPOT MAT'!E88 -> 15.821781 | R88: 1.1
A89: =YEAR(D89) -> 2025 | B89: =DATE(A89,MONTH(D89),1) -> 45992 | C89: mar | D89: =+ D88+1 -> 46000 | E89: 44.732648 | F89: =+'Mono SPOT MAT'!M89/'Fisico SPOT MAT'!M89/24 -> 39.734637 | G89: =16*R89 -> 17.6 | H89: =+'Mono ASIG'!AA89 -> 63.943977 | I89: =+H89-J89*384/744/0.52 -> 46.474994 | J89: =16*R89 -> 17.6 | K89: =+'Mono SPOT MAT'!T89 -> 0 | N89: =+'Mono SPOT MAT'!S89/'Fisico SPOT MAT'!S89/'Fisico SPOT MAT'!E89 -> 15.758849 | R89: 1.1
A90: =YEAR(D90) -> 2025 | B90: =DATE(A90,MONTH(D90),1) -> 45992 | C90: mié | D90: =+ D89+1 -> 46001 | E90: 42.887197 | F90: =+'Mono SPOT MAT'!M90/'Fisico SPOT MAT'!M90/24 -> 40.253765 | G90: =16*R90 -> 17.6 | H90: =+'Mono ASIG'!AA90 -> 59.940251 | I90: =+H90-J90*384/744/0.52 -> 42.471268 | J90: =16*R90 -> 17.6 | K90: =+'Mono SPOT MAT'!T90 -> 0 | N90: =+'Mono SPOT MAT'!S90/'Fisico SPOT MAT'!S90/'Fisico SPOT MAT'!E90 -> 15.797692 | R90: 1.1
...

Sheet Fisico ASIG
B1: Mercado ASIGNADO | O1: ASIGNADA - POTENCIA
B2: Energía Generada por tipo
B3: Potencia disponible por día
F5: ENERGIA | G5: ENERGIA | H5: ENERGIA | I5: ENERGIA | J5: ENERGIA | K5: ENERGIA | L5: ENERGIA | M5: ENERGIA | N5: ENERGIA | O5: POTENCIA | P5: POTENCIA | Q5: POTENCIA | R5: POTENCIA | S5: POTENCIA | T5: POTENCIA | U5: POTENCIA | V5: POTENCIA | W5: POTENCIA
C6: VALORES FISICOS - ACUMULADO MES | F6: MW med | G6: MW med | H6: MW med | I6: MW med | J6: MW med | K6: MW med | L6: MW med | M6: MW med | N6: MW med | O6: MW disp | P6: MW disp | Q6: MW disp | R6: MW disp | S6: MW disp | T6: MW disp | U6: MW disp | V6: MW disp | W6: MW disp
D7: promedio MW/dia | E7: MES | F7: YACYRETA | G7: SALTO GRANDE | H7: HIDRO NAC Resto | I7: HIDRO COM CONCESION | J7: NUCLEAR | K7: PPA RENOV | L7: PPA TERM | M7: IMPORTACION | N7: ENER ASIG | O7: YACYRETA | P7: SALTO GRANDE | Q7: HIDRO NAC Resto | R7: HIDRO COM CONCESION | S7: NUCLEAR | T7: PPA RENOV | U7: PPA TERM | V7: IMPORTACION | W7: POT ASIG
E8: =+Precios!D7 -> 45962 | F8: =AVERAGEIFS(F$20:F$1048576,$B$20:$B$1048576,$E8) -> 2017.5955 | G8: =AVERAGEIFS(G$20:G$1048576,$B$20:$B$1048576,$E8) -> 555.64954 | H8: =AVERAGEIFS(H$20:H$1048576,$B$20:$B$1048576,$E8) -> 887.6217 | I8: =IFERROR(AVERAGEIFS(I$20:I$1048576,$B$20:$B$1048576,$E8),"-") -> - | J8: =AVERAGEIFS(J$20:J$1048576,$B$20:$B$1048576,$E8) -> 1259.5973 | K8: =AVERAGEIFS(K$20:K$1048576,$B$20:$B$1048576,$E8) -> 1752.0802 | L8: =AVERAGEIFS(L$20:L$1048576,$B$20:$B$1048576,$E8) -> 1973.3487 | M8: =AVERAGEIFS(M$20:M$1048576,$B$20:$B$1048576,$E8) -> 24.52265 | N8: =+SUM(F8:M8) -> 8470.4155 | O8: =AVERAGEIFS(O$20:O$1048576,$B$20:$B$1048576,$E8) -> 1500 | P8: =AVERAGEIFS(P$20:P$1048576,$B$20:$B$1048576,$E8) -> 842.66661 | Q8: =AVERAGEIFS(Q$20:Q$1048576,$B$20:$B$1048576,$E8) -> 5079.0934 | S8: =AVERAGEIFS(S$20:S$1048576,$B$20:$B$1048576,$E8) -> 1755 | T8: =AVERAGEIFS(T$20:T$1048576,$B$20:$B$1048576,$E8) -> 0 | U8: =AVERAGEIFS(U$20:U$1048576,$B$20:$B$1048576,$E8) -> 5296.6354 | V8: =AVERAGEIFS(V$20:V$1048576,$B$20:$B$1048576,$E8) -> 0 | W8: =+SUM(O8:V8) -> 14473.395
E9: =+Precios!D8 -> 45992 | F9: =AVERAGEIFS(F$20:F$1048576,$B$20:$B$1048576,$E9) -> 1809.1539 | G9: =AVERAGEIFS(G$20:G$1048576,$B$20:$B$1048576,$E9) -> 386.73617 | H9: =AVERAGEIFS(H$20:H$1048576,$B$20:$B$1048576,$E9) -> 814.48058 | I9: =IFERROR(AVERAGEIFS(I$20:I$1048576,$B$20:$B$1048576,$E9),"-") -> - | J9: =AVERAGEIFS(J$20:J$1048576,$B$20:$B$1048576,$E9) -> 1243.1001 | K9: =AVERAGEIFS(K$20:K$1048576,$B$20:$B$1048576,$E9) -> 1850.225 | L9: =AVERAGEIFS(L$20:L$1048576,$B$20:$B$1048576,$E9) -> 2942.6651 | M9: =AVERAGEIFS(M$20:M$1048576,$B$20:$B$1048576,$E9) -> 75.102478 | N9: =+SUM(F9:M9) -> 9121.4633 | O9: =AVERAGEIFS(O$20:O$1048576,$B$20:$B$1048576,$E9) -> 1500 | P9: =AVERAGEIFS(P$20:P$1048576,$B$20:$B$1048576,$E9) -> 892.71694 | Q9: =AVERAGEIFS(Q$20:Q$1048576,$B$20:$B$1048576,$E9) -> 5261.9461 | S9: =AVERAGEIFS(S$20:S$1048576,$B$20:$B$1048576,$E9) -> 1755 | T9: =AVERAGEIFS(T$20:T$1048576,$B$20:$B$1048576,$E9) -> 0 | U9: =AVERAGEIFS(U$20:U$1048576,$B$20:$B$1048576,$E9) -> 5727.8809 | V9: =AVERAGEIFS(V$20:V$1048576,$B$20:$B$1048576,$E9) -> 0 | W9: =+SUM(O9:V9) -> 15137.544
E10: =+Precios!D9 -> 46023 | F10: =AVERAGEIFS(F$20:F$1048576,$B$20:$B$1048576,$E10) -> 1269.4977 | G10: =AVERAGEIFS(G$20:G$1048576,$B$20:$B$1048576,$E10) -> 548.6778 | H10: =AVERAGEIFS(H$20:H$1048576,$B$20:$B$1048576,$E10) -> 353.4675 | I10: =AVERAGEIFS(I$20:I$1048576,$B$20:$B$1048576,$E10) -> 678.96589 | J10: =AVERAGEIFS(J$20:J$1048576,$B$20:$B$1048576,$E10) -> 1253.595 | K10: =AVERAGEIFS(K$20:K$1048576,$B$20:$B$1048576,$E10) -> 1731.0907 | L10: =AVERAGEIFS(L$20:L$1048576,$B$20:$B$1048576,$E10) -> 3019.2708 | M10: =AVERAGEIFS(M$20:M$1048576,$B$20:$B$1048576,$E10) -> 203.58483 | N10: =+SUM(F10:M10) -> 9058.1502 | O10: =AVERAGEIFS(O$20:O$1048576,$B$20:$B$1048576,$E10) -> 1500 | P10: =AVERAGEIFS(P$20:P$1048576,$B$20:$B$1048576,$E10) -> 922.52379 | Q10: =AVERAGEIFS(Q$20:Q$1048576,$B$20:$B$1048576,$E10) -> 2204.7347 | R10: =AVERAGEIFS(R$20:R$1048576,$B$20:$B$1048576,$E10) -> 3896.0358 | S10: =AVERAGEIFS(S$20:S$1048576,$B$20:$B$1048576,$E10) -> 1755 | T10: =AVERAGEIFS(T$20:T$1048576,$B$20:$B$1048576,$E10) -> 0 | U10: =AVERAGEIFS(U$20:U$1048576,$B$20:$B$1048576,$E10) -> 5820.8805 | V10: =AVERAGEIFS(V$20:V$1048576,$B$20:$B$1048576,$E10) -> 0 | W10: =+SUM(O10:V10) -> 16099.175
E11: =+Precios!D10 -> 46054 | F11: =AVERAGEIFS(F$20:F$1048576,$B$20:$B$1048576,$E11) -> 985.05709 | G11: =AVERAGEIFS(G$20:G$1048576,$B$20:$B$1048576,$E11) -> 245.57043 | H11: =AVERAGEIFS(H$20:H$1048576,$B$20:$B$1048576,$E11) -> 243.47859 | I11: =AVERAGEIFS(I$20:I$1048576,$B$20:$B$1048576,$E11) -> 481.37719 | J11: =AVERAGEIFS(J$20:J$1048576,$B$20:$B$1048576,$E11) -> 1234.5675 | K11: =AVERAGEIFS(K$20:K$1048576,$B$20:$B$1048576,$E11) -> 1782.9666 | L11: =AVERAGEIFS(L$20:L$1048576,$B$20:$B$1048576,$E11) -> 3090.1065 | M11: =AVERAGEIFS(M$20:M$1048576,$B$20:$B$1048576,$E11) -> 195.57906 | N11: =+SUM(F11:M11) -> 8258.7029 | O11: =AVERAGEIFS(O$20:O$1048576,$B$20:$B$1048576,$E11) -> 1500 | P11: =AVERAGEIFS(P$20:P$1048576,$B$20:$B$1048576,$E11) -> 899.3488 | Q11: =AVERAGEIFS(Q$20:Q$1048576,$B$20:$B$1048576,$E11) -> 1026.3623 | R11: =AVERAGEIFS(R$20:R$1048576,$B$20:$B$1048576,$E11) -> 3856.4639 | S11: =AVERAGEIFS(S$20:S$1048576,$B$20:$B$1048576,$E11) -> 1755 | T11: =AVERAGEIFS(T$20:T$1048576,$B$20:$B$1048576,$E11) -> 0 | U11: =AVERAGEIFS(U$20:U$1048576,$B$20:$B$1048576,$E11) -> 5825.4073 | V11: =AVERAGEIFS(V$20:V$1048576,$B$20:$B$1048576,$E11) -> 0 | W11: =+SUM(O11:V11) -> 14862.582
E12: =+Precios!D11 -> 46082 | F12: =AVERAGEIFS(F$20:F$1048576,$B$20:$B$1048576,$E12) -> 1031.0641 | G12: =AVERAGEIFS(G$20:G$1048576,$B$20:$B$1048576,$E12) -> 237.71785 | H12: =AVERAGEIFS(H$20:H$1048576,$B$20:$B$1048576,$E12) -> 247.8823 | I12: =AVERAGEIFS(I$20:I$1048576,$B$20:$B$1048576,$E12) -> 595.96721 | J12: =AVERAGEIFS(J$20:J$1048576,$B$20:$B$1048576,$E12) -> 792.34466 | K12: =AVERAGEIFS(K$20:K$1048576,$B$20:$B$1048576,$E12) -> 1740.137 | L12: =AVERAGEIFS(L$20:L$1048576,$B$20:$B$1048576,$E12) -> 3012.0061 | M12: =AVERAGEIFS(M$20:M$1048576,$B$20:$B$1048576,$E12) -> 109.93972 | N12: =+SUM(F12:M12) -> 7767.0589 | O12: =AVERAGEIFS(O$20:O$1048576,$B$20:$B$1048576,$E12) -> 1500 | P12: =AVERAGEIFS(P$20:P$1048576,$B$20:$B$1048576,$E12) -> 804.5187 | Q12: =AVERAGEIFS(Q$20:Q$1048576,$B$20:$B$1048576,$E12) -> 1006.4949 | R12: =AVERAGEIFS(R$20:R$1048576,$B$20:$B$1048576,$E12) -> 3800.676 | S12: =AVERAGEIFS(S$20:S$1048576,$B$20:$B$1048576,$E12) -> 1755 | T12: =AVERAGEIFS(T$20:T$1048576,$B$20:$B$1048576,$E12) -> 0 | U12: =AVERAGEIFS(U$20:U$1048576,$B$20:$B$1048576,$E12) -> 5369.8895 | V12: =AVERAGEIFS(V$20:V$1048576,$B$20:$B$1048576,$E12) -> 0 | W12: =+SUM(O12:V12) -> 14236.579
E13: =+Precios!D12 -> 46113 | F13: =AVERAGEIFS(F$20:F$1048576,$B$20:$B$1048576,$E13) -> 1375.4281 | G13: =AVERAGEIFS(G$20:G$1048576,$B$20:$B$1048576,$E13) -> 333.06879 | H13: =AVERAGEIFS(H$20:H$1048576,$B$20:$B$1048576,$E13) -> 250.78597 | I13: =AVERAGEIFS(I$20:I$1048576,$B$20:$B$1048576,$E13) -> 583.99947 | J13: =AVERAGEIFS(J$20:J$1048576,$B$20:$B$1048576,$E13) -> 599.63981 | K13: =AVERAGEIFS(K$20:K$1048576,$B$20:$B$1048576,$E13) -> 1634.2925 | L13: =AVERAGEIFS(L$20:L$1048576,$B$20:$B$1048576,$E13) -> 2396.1315 | M13: =AVERAGEIFS(M$20:M$1048576,$B$20:$B$1048576,$E13) -> 251.91863 | N13: =+SUM(F13:M13) -> 7425.2648 | O13: =AVERAGEIFS(O$20:O$1048576,$B$20:$B$1048576,$E13) -> 1500 | P13: =AVERAGEIFS(P$20:P$1048576,$B$20:$B$1048576,$E13) -> 827.57642 | Q13: =AVERAGEIFS(Q$20:Q$1048576,$B$20:$B$1048576,$E13) -> 969.32118 | R13: =AVERAGEIFS(R$20:R$1048576,$B$20:$B$1048576,$E13) -> 3717.7575 | S13: =AVERAGEIFS(S$20:S$1048576,$B$20:$B$1048576,$E13) -> 1755 | T13: =AVERAGEIFS(T$20:T$1048576,$B$20:$B$1048576,$E13) -> 0 | U13: =AVERAGEIFS(U$20:U$1048576,$B$20:$B$1048576,$E13) -> 5122.7089 | V13: =AVERAGEIFS(V$20:V$1048576,$B$20:$B$1048576,$E13) -> 0 | W13: =+SUM(O13:V13) -> 13892.364
E14: =+Precios!D13 -> 46143 | F14: =AVERAGEIFS(F$20:F$1048576,$B$20:$B$1048576,$E14) -> 1564.0244 | G14: =AVERAGEIFS(G$20:G$1048576,$B$20:$B$1048576,$E14) -> 451.72274 | H14: =AVERAGEIFS(H$20:H$1048576,$B$20:$B$1048576,$E14) -> 297.85809 | I14: =AVERAGEIFS(I$20:I$1048576,$B$20:$B$1048576,$E14) -> 1073.5445 | J14: =AVERAGEIFS(J$20:J$1048576,$B$20:$B$1048576,$E14) -> 1046.1918 | K14: =AVERAGEIFS(K$20:K$1048576,$B$20:$B$1048576,$E14) -> 1429.5537 | L14: =AVERAGEIFS(L$20:L$1048576,$B$20:$B$1048576,$E14) -> 2289.658 | M14: =AVERAGEIFS(M$20:M$1048576,$B$20:$B$1048576,$E14) -> 1020.0108 | N14: =+SUM(F14:M14) -> 9172.5639 | O14: =AVERAGEIFS(O$20:O$1048576,$B$20:$B$1048576,$E14) -> 1500 | P14: =AVERAGEIFS(P$20:P$1048576,$B$20:$B$1048576,$E14) -> 886.00852 | Q14: =AVERAGEIFS(Q$20:Q$1048576,$B$20:$B$1048576,$E14) -> 998.39305 | R14: =AVERAGEIFS(R$20:R$1048576,$B$20:$B$1048576,$E14) -> 3579.6586 | S14: =AVERAGEIFS(S$20:S$1048576,$B$20:$B$1048576,$E14) -> 1755 | T14: =AVERAGEIFS(T$20:T$1048576,$B$20:$B$1048576,$E14) -> 0 | U14: =AVERAGEIFS(U$20:U$1048576,$B$20:$B$1048576,$E14) -> 5148.9697 | V14: =AVERAGEIFS(V$20:V$1048576,$B$20:$B$1048576,$E14) -> 0 | W14: =+SUM(O14:V14) -> 13868.03
E15: =+Precios!D14 -> 46174 | F15: =AVERAGEIFS(F$20:F$1048576,$B$20:$B$1048576,$E15) -> 1623.6642 | G15: =AVERAGEIFS(G$20:G$1048576,$B$20:$B$1048576,$E15) -> 269.48917 | H15: =AVERAGEIFS(H$20:H$1048576,$B$20:$B$1048576,$E15) -> 256.91911 | I15: =AVERAGEIFS(I$20:I$1048576,$B$20:$B$1048576,$E15) -> 741.59541 | J15: =AVERAGEIFS(J$20:J$1048576,$B$20:$B$1048576,$E15) -> 1207.9871 | K15: =AVERAGEIFS(K$20:K$1048576,$B$20:$B$1048576,$E15) -> 1522.5435 | L15: =AVERAGEIFS(L$20:L$1048576,$B$20:$B$1048576,$E15) -> 2469.8278 | M15: =AVERAGEIFS(M$20:M$1048576,$B$20:$B$1048576,$E15) -> 1123.3672 | N15: =+SUM(F15:M15) -> 9215.3935 | O15: =AVERAGEIFS(O$20:O$1048576,$B$20:$B$1048576,$E15) -> 1500 | P15: =AVERAGEIFS(P$20:P$1048576,$B$20:$B$1048576,$E15) -> 866.86158 | Q15: =AVERAGEIFS(Q$20:Q$1048576,$B$20:$B$1048576,$E15) -> 969.96831 | R15: =AVERAGEIFS(R$20:R$1048576,$B$20:$B$1048576,$E15) -> 3621.3354 | S15: =AVERAGEIFS(S$20:S$1048576,$B$20:$B$1048576,$E15) -> 1755 | T15: =AVERAGEIFS(T$20:T$1048576,$B$20:$B$1048576,$E15) -> 0 | U15: =AVERAGEIFS(U$20:U$1048576,$B$20:$B$1048576,$E15) -> 5791.3707 | V15: =AVERAGEIFS(V$20:V$1048576,$B$20:$B$1048576,$E15) -> 0 | W15: =+SUM(O15:V15) -> 14504.536
C17: VALORES FISICOS - PASO DIARIO | F17: ENERGIA | G17: ENERGIA | H17: ENERGIA | I17: ENERGIA | J17: ENERGIA | K17: ENERGIA | L17: ENERGIA | M17: ENERGIA | N17: ENERGIA | O17: POTENCIA | P17: POTENCIA | Q17: POTENCIA | R17: POTENCIA | S17: POTENCIA | T17: POTENCIA | U17: POTENCIA | V17: POTENCIA | W17: POTENCIA
F18: MW med | G18: MW med | H18: MW med | I18: MW med | J18: MW med | K18: MW med | L18: MW med | M18: MW med | N18: MW med | O18: MW disp | P18: MW disp | Q18: MW disp | R18: MW disp | S18: MW disp | T18: MW disp | U18: MW disp | V18: MW disp | W18: MW disp
A19: AÑO | B19: MES | C19: # dias/mes | D19: TIPO dia | E19: DIA | F19: YACYRETA | G19: SALTO GRANDE | H19: HIDRO NAC Resto | I19: HIDRO COM CONCESION | J19: NUCLEAR | K19: PPA RENOV | L19: PPA TERM | M19: IMPORTACION | N19: ENER ASIG | O19: YACYRETA | P19: SALTO GRANDE | Q19: HIDRO NAC Resto | R19: HIDRO COM CONCESION | S19: NUCLEAR | T19: PPA RENOV | U19: PPA TERM | V19: IMPORTACION | W19: POT ASIG
A20: =YEAR(E20) -> 2025 | B20: =DATE(A20,MONTH(E20),1) -> 45931 | C20: 31 | D20: mié. | E20: 45931 | F20: 1815.8247 | G20: 733.327 | H20: 754.569 | J20: 915.93338 | K20: 2226.5328 | L20: 1431.3534 | M20: 237.28671 | N20: =SUM(F20:M20) -> 8114.827 | O20: 1500 | P20: 791.63437 | Q20: 5516.6738 | S20: 1755 | T20: 0 | U20: 4819.1509 | V20: 0 | W20: =SUM(O20:V20) -> 14382.459
A21: =YEAR(E21) -> 2025 | B21: =DATE(A21,MONTH(E21),1) -> 45931 | C21: 31 | D21: jue. | E21: =+ E20+1 -> 45932 | F21: 1949.3443 | G21: 745.48846 | H21: 703.37642 | J21: 1258.4156 | K21: 2009.3687 | L21: 1408.0382 | M21: 277.71912 | N21: =SUM(F21:M21) -> 8351.7507 | O21: 1500 | P21: 808.47812 | Q21: 5504.205 | S21: 1755 | T21: 0 | U21: 4860.7804 | V21: 0 | W21: =SUM(O21:V21) -> 14428.464
A22: =YEAR(E22) -> 2025 | B22: =DATE(A22,MONTH(E22),1) -> 45931 | C22: 31 | D22: vie. | E22: =+ E21+1 -> 45933 | F22: 1939.6475 | G22: 749.67129 | H22: 961.37013 | J22: 1264.0865 | K22: 1946.2811 | L22: 1451.441 | M22: 243.12 | N22: =SUM(F22:M22) -> 8555.6174 | O22: 1500 | P22: 823.2 | Q22: 5506.8017 | S22: 1755 | T22: 0 | U22: 4945.3649 | V22: 0 | W22: =SUM(O22:V22) -> 14530.367
A23: =YEAR(E23) -> 2025 | B23: =DATE(A23,MONTH(E23),1) -> 45931 | C23: 31 | D23: sáb. | E23: =+ E22+1 -> 45934 | F23: 1438.7366 | G23: 724.03604 | H23: 941.07954 | J23: 1263.1498 | K23: 1780.7511 | L23: 1782.2303 | M23: 390.35292 | N23: =SUM(F23:M23) -> 8320.3363 | O23: 1500 | P23: 773.85 | Q23: 5526.5394 | S23: 1755 | T23: 0 | U23: 5447.4902 | V23: 0 | W23: =SUM(O23:V23) -> 15002.88
A24: =YEAR(E24) -> 2025 | B24: =DATE(A24,MONTH(E24),1) -> 45931 | C24: 31 | D24: dom. | E24: =+ E23+1 -> 45935 | F24: 1269.1058 | G24: 744.76929 | H24: 785.91979 | J24: 1262.7215 | K24: 1435.3352 | L24: 1583.318 | M24: 388.39271 | N24: =SUM(F24:M24) -> 7469.5624 | O24: 1500 | P24: 806.4 | Q24: 5529.8206 | S24: 1755 | T24: 0 | U24: 5519.7136 | V24: 0 | W24: =SUM(O24:V24) -> 15110.934
A25: =YEAR(E25) -> 2025 | B25: =DATE(A25,MONTH(E25),1) -> 45931 | C25: 31 | D25: lun. | E25: =+ E24+1 -> 45936 | F25: 1395.5035 | G25: 808.06504 | H25: 995.723 | J25: 1265.3228 | K25: 1864.646 | L25: 1753.2998 | M25: 454.37788 | N25: =SUM(F25:M25) -> 8536.938 | O25: 1500 | P25: 866.775 | Q25: 5426.6389 | S25: 1755 | T25: 0 | U25: 5682.5243 | V25: 0 | W25: =SUM(O25:V25) -> 15230.938
A26: =YEAR(E26) -> 2025 | B26: =DATE(A26,MONTH(E26),1) -> 45931 | C26: 31 | D26: mar. | E26: =+ E25+1 -> 45937 | F26: 1526.2629 | G26: 806.14721 | H26: 730.13079 | J26: 1262.5886 | K26: 1904.3338 | L26: 1640.3768 | M26: 392.88387 | N26: =SUM(F26:M26) -> 8262.724 | O26: 1500 | P26: 866.775 | Q26: 5416.7982 | S26: 1755 | T26: 0 | U26: 5766.5573 | V26: 0 | W26: =SUM(O26:V26) -> 15305.131
A27: =YEAR(E27) -> 2025 | B27: =DATE(A27,MONTH(E27),1) -> 45931 | C27: 31 | D27: mié. | E27: =+ E26+1 -> 45938 | F27: 1752.877 | G27: 789.48825 | H27: 513.77558 | J27: 1261.121 | K27: 2365.9218 | L27: 1484.0511 | M27: 231.80233 | N27: =SUM(F27:M27) -> 8399.0371 | O27: 1500 | P27: 921.375 | Q27: 5403.7869 | S27: 1755 | T27: 0 | U27: 5766.4922 | V27: 0 | W27: =SUM(O27:V27) -> 15346.654
A28: =YEAR(E28) -> 2025 | B28: =DATE(A28,MONTH(E28),1) -> 45931 | C28: 31 | D28: jue. | E28: =+ E27+1 -> 45939 | F28: 1707.2012 | G28: 786.09621 | H28: 696.89167 | J28: 1263.1178 | K28: 2157.2767 | L28: 1449.6966 | M28: 333.56487 | N28: =SUM(F28:M28) -> 8393.845 | O28: 1500 | P28: 845.25 | Q28: 5417.7331 | S28: 1755 | T28: 0 | U28: 5662.2557 | V28: 0 | W28: =SUM(O28:V28) -> 15180.239
A29: =YEAR(E29) -> 2025 | B29: =DATE(A29,MONTH(E29),1) -> 45931 | C29: 31 | D29: vie. | E29: =+ E28+1 -> 45940 | F29: 1531.6256 | G29: 797.369 | H29: 752.35717 | J29: 1261.3803 | K29: 1617.7095 | L29: 1350.1886 | M29: 392.8985 | N29: =SUM(F29:M29) -> 7703.5286 | O29: 1500 | P29: 863.1 | Q29: 5410.6675 | S29: 1755 | T29: 0 | U29: 5621.8471 | V29: 0 | W29: =SUM(O29:V29) -> 15150.615
A30: =YEAR(E30) -> 2025 | B30: =DATE(A30,MONTH(E30),1) -> 45931 | C30: 31 | D30: sáb. | E30: =+ E29+1 -> 45941 | F30: 1190.0365 | G30: 803.90588 | H30: 989.83675 | J30: 1261.7599 | K30: 1695.1419 | L30: 1465.5125 | M30: 459.20975 | N30: =SUM(F30:M30) -> 7865.4032 | O30: 1500 | P30: 863.1 | Q30: 5421.1093 | S30: 1755 | T30: 0 | U30: 5674.1109 | V30: 0 | W30: =SUM(O30:V30) -> 15213.32
A31: =YEAR(E31) -> 2025 | B31: =DATE(A31,MONTH(E31),1) -> 45931 | C31: 31 | D31: dom. | E31: =+ E30+1 -> 45942 | F31: 1351.191 | G31: 738.99133 | H31: 346.50833 | J31: 1263.5628 | K31: 2058.52 | L31: 1599.3693 | M31: 149.024 | N31: =SUM(F31:M31) -> 7507.1667 | O31: 1500 | P31: 793.275 | Q31: 5454.68 | S31: 1755 | T31: 0 | U31: 5743.3811 | V31: 0 | W31: =SUM(O31:V31) -> 15246.336
A32: =YEAR(E32) -> 2025 | B32: =DATE(A32,MONTH(E32),1) -> 45931 | C32: 31 | D32: lun. | E32: =+ E31+1 -> 45943 | F32: 2007.1348 | G32: 791.20429 | H32: 704.90517 | J32: 1262.6753 | K32: 2101.7496 | L32: 1450.4282 | M32: 391.76054 | N32: =SUM(F32:M32) -> 8709.8579 | O32: 1500 | P32: 849.45 | Q32: 5243.6318 | S32: 1755 | T32: 0 | U32: 5646.301 | V32: 0 | W32: =SUM(O32:V32) -> 14994.383
... A50: =YEAR(E50) -> 2025 | B50: =DATE(A50,MONTH(E50),1) -> 45931 | C50: 31 | D50: vie. | E50: =+ E49+1 -> 45961 | F50: 2095.6783 | G50: 657.10521 | H50: 516.52708 | J50: 1267.4595 | K50: 2283.1108 | L50: 1707.1944 | M50: 17.609167 | N50: =SUM(F50:M50) -> 8544.6844 | O50: 1500 | P50: 850.5 | Q50: 4727.6425 | S50: 1755 | T50: 0 | U50: 5142.6631 | V50: 0 | W50: =SUM(O50:V50) -> 13975.806
A51: =YEAR(E51) -> 2025 | B51: =DATE(A51,MONTH(E51),1) -> 45962 | C51: 30 | D51: sáb. | E51: 45962 | F51: 2209.085 | G51: 321.88921 | H51: 697.51738 | J51: 1266.7247 | K51: 2017.0351 | L51: 1499.8579 | M51: 13.447542 | N51: =SUM(F51:M51) -> 8025.5568 | O51: 1500 | P51: 831.075 | Q51: 4763.8894 | S51: 1755 | T51: 0 | U51: 5101.2881 | V51: 0 | W51: =+SUM(O51:V51) -> 13951.252
A52: =YEAR(E52) -> 2025 | B52: =DATE(A52,MONTH(E52),1) -> 45962 | C52: 30 | D52: dom. | E52: 45963 | F52: 1940.7099 | G52: 181.6755 | H52: 685.36642 | J52: 1268.5178 | K52: 1604.6535 | L52: 1644.6367 | M52: 12.637542 | N52: =SUM(F52:M52) -> 7338.1975 | O52: 1500 | P52: 799.575 | Q52: 4958.6863 | S52: 1755 | T52: 0 | U52: 5145.2362 | V52: 0 | W52: =+SUM(O52:V52) -> 14158.497
A53: =YEAR(E53) -> 2025 | B53: =DATE(A53,MONTH(E53),1) -> 45962 | C53: 30 | D53: lun. | E53: 45964 | F53: 2566.9223 | G53: 742.09762 | H53: 1171.6898 | J53: 1263.4837 | K53: 1371.3671 | L53: 2205.5945 | M53: 19.220458 | N53: =SUM(F53:M53) -> 9340.3756 | O53: 1500 | P53: 862.21844 | Q53: 5174.4613 | S53: 1755 | T53: 0 | U53: 5164.9815 | V53: 0 | W53: =+SUM(O53:V53) -> 14456.661
A54: =YEAR(E54) -> 2025 | B54: =DATE(A54,MONTH(E54),1) -> 45962 | C54: 30 | D54: mar. | E54: 45965 | F54: 2120.224 | G54: 804.13142 | H54: 1297.0475 | J54: 1266.0334 | K54: 1669.3403 | L54: 2117.4936 | M54: 47.099333 | N54: =SUM(F54:M54) -> 9321.3697 | O54: 1500 | P54: 884.10831 | Q54: 5172.0331 | S54: 1755 | T54: 0 | U54: 5235.2733 | V54: 0 | W54: =+SUM(O54:V54) -> 14546.415
A55: =YEAR(E55) -> 2025 | B55: =DATE(A55,MONTH(E55),1) -> 45962 | C55: 30 | D55: mié. | E55: 45966 | F55: 2221.3129 | G55: 799.9175 | H55: 990.329 | J55: 1265.661 | K55: 1646.794 | L55: 1572.1316 | M55: 57.503583 | N55: =SUM(F55:M55) -> 8553.6496 | O55: 1500 | P55: 866.55691 | Q55: 5047.6195 | S55: 1755 | T55: 0 | U55: 5238.7988 | V55: 0 | W55: =+SUM(O55:V55) -> 14407.975
A56: =YEAR(E56) -> 2025 | B56: =DATE(A56,MONTH(E56),1) -> 45962 | C56: 30 | D56: jue. | E56: 45967 | F56: 2147.8214 | G56: 787.643 | H56: 837.57121 | J56: 1265.9419 | K56: 1514.5848 | L56: 1761.9135 | M56: 38.018708 | N56: =SUM(F56:M56) -> 8353.4945 | O56: 1500 | P56: 895.125 | Q56: 4908.7938 | S56: 1755 | T56: 0 | U56: 5394.4889 | V56: 0 | W56: =+SUM(O56:V56) -> 14453.408
A57: =YEAR(E57) -> 2025 | B57: =DATE(A57,MONTH(E57),1) -> 45962 | C57: 30 | D57: vie | E57: 45968 | F57: 2202.98 | G57: 769.01133 | H57: 822.90487 | J57: 1261.0498 | K57: 1312.7663 | L57: 2052.2768 | M57: 45.161875 | N57: =SUM(F57:M57) -> 8466.1509 | O57: 1500 | P57: 883.21319 | Q57: 5105.8175 | S57: 1755 | T57: 0 | U57: 5449.7766 | V57: 0 | W57: =+SUM(O57:V57) -> 14693.807
A58: =YEAR(E58) -> 2025 | B58: =DATE(A58,MONTH(E58),1) -> 45962 | C58: 30 | D58: sáb | E58: 45969 | F58: 2482.1984 | G58: 736.43033 | H58: 711.33679 | J58: 1266.0703 | K58: 1080.0504 | L58: 1843.7426 | M58: 35.545167 | N58: =SUM(F58:M58) -> 8155.374 | O58: 1500 | P58: 884.70375 | Q58: 5093.13 | S58: 1755 | T58: 0 | U58: 5468.7402 | V58: 0 | W58: =+SUM(O58:V58) -> 14701.574
A59: =YEAR(E59) -> 2025 | B59: =DATE(A59,MONTH(E59),1) -> 45962 | C59: 30 | D59: dom | E59: 45970 | F59: 2482.1747 | G59: 697.45429 | H59: 667.476 | J59: 1264.5537 | K59: 1179.0226 | L59: 1497.2533 | M59: 17.823583 | N59: =SUM(F59:M59) -> 7805.7581 | O59: 1500 | P59: 896.7 | Q59: 5097.505 | S59: 1755 | T59: 0 | U59: 5364.1029 | V59: 0 | W59: =+SUM(O59:V59) -> 14613.308
...

Sheet Mono ASIG
B1: Mercado ASIGNADO | H1: $ ASIGNADA - ENERGIA $ | Q1: $ ASIGNADA - POTENCIA $ | Z1: $ ASIGNADA $
B2: PRECIOS UNITARIOS REPRESENTATIVOS
B3: Por Energía / Por Potencia
H5: VARIABLES | I5: VARIABLES | J5: VARIABLES | K5: VARIABLES | L5: VARIABLES | M5: VARIABLES | N5: VARIABLES | O5: VARIABLES | P5: VARIABLES | Q5: FIJOS | R5: FIJOS | S5: FIJOS | T5: FIJOS | U5: FIJOS | V5: FIJOS | W5: FIJOS | X5: FIJOS | Y5: FIJOS | Z5: FIJ + VAR | AA5: FIJ + VAR | AB5: FIJ + VAR | AC5: FIJ + VAR
E6: VALORES ECONOMICOS - ACUMULADO MES | H6: usd/MWh | I6: usd/MWh | J6: usd/MWh | K6: usd/MWh | L6: usd/MWh | M6: usd/MWh | N6: usd/MWh | O6: usd/MWh | P6: usd/dia | Q6: usd/MW mes | R6: usd/MW mes | S6: usd/MW mes | T6: usd/MW mes | U6: usd/MW mes | V6: usd/MW mes | W6: usd/MW mes | X6: usd/MW mes | Y6: =+P6 -> usd/dia | Z6: =+Y6 -> usd/dia | AA6: usd/Mwh | AB6: usd/Mwh | AC6: usd/Mwh
G7: MES | H7: YACYRETA | I7: SALTO GRANDE | J7: HIDRO NAC Resto | K7: HIDRO COM CONCESION | L7: NUCLEAR | M7: PPA RENOV | N7: PPA TERM | O7: IMPORTACION | P7: VAR ASIG | Q7: YACYRETA | R7: SALTO GRANDE | S7: HIDRO NAC Resto | T7: HIDRO COM CONCESION | U7: NUCLEAR | V7: PPA RENOV | W7: PPA TERM | X7: IMPORTACION | Y7: FIJOS ASIG | Z7: SUMA ASIG | AA7: MONO | AB7: POT | AC7: ENER
G8: =+'Fisico ASIG'!E8 -> 45962 | H8: =AVERAGEIFS(H$20:H$1048576,$D$20:$D$1048576,$G8) -> 28 | I8: =AVERAGEIFS(I$20:I$1048576,$D$20:$D$1048576,$G8) -> 4.7975185 | J8: =AVERAGEIFS(J$20:J$1048576,$D$20:$D$1048576,$G8) -> 5.8161641 | L8: =AVERAGEIFS(L$20:L$1048576,$D$20:$D$1048576,$G8) -> 27 | M8: =AVERAGEIFS(M$20:M$1048576,$D$20:$D$1048576,$G8) -> 71.5 | N8: =AVERAGEIFS(N$20:N$1048576,$D$20:$D$1048576,$G8) -> 38.068552 | O8: =AVERAGEIFS(O$20:O$1048576,$D$20:$D$1048576,$G8) -> 92.860415 | P8: =AVERAGEIFS(P$20:P$1048576,$D$20:$D$1048576,$G8) -> 7220427.9 | Q8: =AVERAGEIFS(Q$20:Q$1048576,$D$20:$D$1048576,$G8) -> 0 | R8: =AVERAGEIFS(R$20:R$1048576,$D$20:$D$1048576,$G8) -> 5497.7825 | S8: =AVERAGEIFS(S$20:S$1048576,$D$20:$D$1048576,$G8) -> 1540.5825 | U8: =AVERAGEIFS(U$20:U$1048576,$D$20:$D$1048576,$G8) -> 18000 | V8: =AVERAGEIFS(V$20:V$1048576,$D$20:$D$1048576,$G8) -> 0 | W8: =AVERAGEIFS(W$20:W$1048576,$D$20:$D$1048576,$G8) -> 21900 | X8: =AVERAGEIFS(X$20:X$1048576,$D$20:$D$1048576,$G8) -> 0 | Y8: =AVERAGEIFS(Y$20:Y$1048576,$D$20:$D$1048576,$G8) -> 5334795.8 | Z8: =+(P8+Y8) -> 12555224 | AA8: =+Z8/'Fisico ASIG'!N8/24 -> 61.760172 | AB8: =+$AB$16*Precios!R7*Precios!P7/Precios!W7/Precios!Q7 -> 13.384615 | AC8: =+AA8-AB8 -> 48.375557
G9: =+'Fisico ASIG'!E9 -> 45992 | H9: =AVERAGEIFS(H$20:H$1048576,$D$20:$D$1048576,$G9) -> 28 | I9: =AVERAGEIFS(I$20:I$1048576,$D$20:$D$1048576,$G9) -> 4.8642721 | J9: =AVERAGEIFS(J$20:J$1048576,$D$20:$D$1048576,$G9) -> 5.7816249 | L9: =AVERAGEIFS(L$20:L$1048576,$D$20:$D$1048576,$G9) -> 27 | M9: =AVERAGEIFS(M$20:M$1048576,$D$20:$D$1048576,$G9) -> 71.5 | N9: =AVERAGEIFS(N$20:N$1048576,$D$20:$D$1048576,$G9) -> 40.46591 | O9: =AVERAGEIFS(O$20:O$1048576,$D$20:$D$1048576,$G9) -> 104.20101 | P9: =AVERAGEIFS(P$20:P$1048576,$D$20:$D$1048576,$G9) -> 8384683.9 | Q9: =AVERAGEIFS(Q$20:Q$1048576,$D$20:$D$1048576,$G9) -> 0 | R9: =AVERAGEIFS(R$20:R$1048576,$D$20:$D$1048576,$G9) -> 5574.4373 | S9: =AVERAGEIFS(S$20:S$1048576,$D$20:$D$1048576,$G9) -> 1706.1611 | U9: =AVERAGEIFS(U$20:U$1048576,$D$20:$D$1048576,$G9) -> 18000 | V9: =AVERAGEIFS(V$20:V$1048576,$D$20:$D$1048576,$G9) -> 0 | W9: =AVERAGEIFS(W$20:W$1048576,$D$20:$D$1048576,$G9) -> 21900 | X9: =AVERAGEIFS(X$20:X$1048576,$D$20:$D$1048576,$G9) -> 0 | Y9: =AVERAGEIFS(Y$20:Y$1048576,$D$20:$D$1048576,$G9) -> 5515635.9 | Z9: =+(P9+Y9) -> 13900320 | AA9: =+Z9/'Fisico ASIG'!N9/24 -> 63.49639 | AB9: =+$AB$16*Precios!R8*Precios!P8/Precios!W8/Precios!Q8 -> 17.468983 | AC9: =+AA9-AB9 -> 46.027408
G10: =+'Fisico ASIG'!E10 -> 46023 | H10: =AVERAGEIFS(H$20:H$1048576,$D$20:$D$1048576,$G10) -> 28 | I10: =AVERAGEIFS(I$20:I$1048576,$D$20:$D$1048576,$G10) -> 5.0018454 | J10: =AVERAGEIFS(J$20:J$1048576,$D$20:$D$1048576,$G10) -> 6.5099399 | K10: =AVERAGEIFS(K$20:K$1048576,$D$20:$D$1048576,$G10) -> 7.5875 | L10: =AVERAGEIFS(L$20:L$1048576,$D$20:$D$1048576,$G10) -> 27 | M10: =AVERAGEIFS(M$20:M$1048576,$D$20:$D$1048576,$G10) -> 71.5 | N10: =AVERAGEIFS(N$20:N$1048576,$D$20:$D$1048576,$G10) -> 42.13139 | O10: =AVERAGEIFS(O$20:O$1048576,$D$20:$D$1048576,$G10) -> 80.830082 | ... Y10: =AVERAGEIFS(Y$20:Y$1048576,$D$20:$D$1048576,$G10) -> 5622846.9 | Z10: =+(P10+Y10) -> 14028881 | AA10: =+Z10/'Fisico ASIG'!N10/24 -> 64.531577 | AB10: =+$AB$16*Precios!R9*Precios!P9/Precios!W9/Precios!Q9 -> 17.559967 | AC10: =+AA10-AB10 -> 46.97161
G11: =+'Fisico ASIG'!E11 -> 46054 | H11: =AVERAGEIFS(H$20:H$1048576,$D$20:$D$1048576,$G11) -> 28 | I11: =AVERAGEIFS(I$20:I$1048576,$D$20:$D$1048576,$G11) -> 5.1392516 | J11: =AVERAGEIFS(J$20:J$1048576,$D$20:$D$1048576,$G11) -> 6.6887752 | K11: =AVERAGEIFS(K$20:K$1048576,$D$20:$D$1048576,$G11) -> 7.5875 | L11: =AVERAGEIFS(L$20:L$1048576,$D$20:$D$1048576,$G11) -> 27 | M11: =AVERAGEIFS(M$20:M$1048576,$D$20:$D$1048576,$G11) -> 71.5 | N11: =AVERAGEIFS(N$20:N$1048576,$D$20:$D$1048576,$G11) -> 41.039718 | O11: =AVERAGEIFS(O$20:O$1048576,$D$20:$D$1048576,$G11) -> 92.10906 | ... Y11: =AVERAGEIFS(Y$20:Y$1048576,$D$20:$D$1048576,$G11) -> 6227666.1 | Z11: =+(P11+Y11) -> 14495266 | AA11: =+Z11/'Fisico ASIG'!N11/24 -> 73.131269 | AB11: =+$AB$16*Precios!R10*Precios!P10/Precios!W10/Precios!Q10 -> 16.923077 | AC11: =+AA11-AB11 -> 56.208193
G12: =+'Fisico ASIG'!E12 -> 46082 | H12: =AVERAGEIFS(H$20:H$1048576,$D$20:$D$1048576,$G12) -> 28 | I12: =AVERAGEIFS(I$20:I$1048576,$D$20:$D$1048576,$G12) -> 5.2366365 | J12: =AVERAGEIFS(J$20:J$1048576,$D$20:$D$1048576,$G12) -> 5.8867926 | K12: =AVERAGEIFS(K$20:K$1048576,$D$20:$D$1048576,$G12) -> 6.8583333 | L12: =AVERAGEIFS(L$20:L$1048576,$D$20:$D$1048576,$G12) -> 27 | M12: =AVERAGEIFS(M$20:M$1048576,$D$20:$D$1048576,$G12) -> 71.5 | N12: =AVERAGEIFS(N$20:N$1048576,$D$20:$D$1048576,$G12) -> 46.488647 | O12: =AVERAGEIFS(O$20:O$1048576,$D$20:$D$1048576,$G12) -> 71.653023 | ... Y12: =AVERAGEIFS(Y$20:Y$1048576,$D$20:$D$1048576,$G12) -> 5289948.7 | Z12: =+(P12+Y12) -> 13267383 | AA12: =+Z12/'Fisico ASIG'!N12/24 -> 71.173352 | AB12: =+$AB$16*Precios!R11*Precios!P11/Precios!W11/Precios!Q11 -> 12.492501 | AC12: =+AA12-AB12 -> 58.680851
G13: =+'Fisico ASIG'!E13 -> 46113 | H13: =AVERAGEIFS(H$20:H$1048576,$D$20:$D$1048576,$G13) -> 28 | I13: =AVERAGEIFS(I$20:I$1048576,$D$20:$D$1048576,$G13) -> 5.2429398 | J13: =AVERAGEIFS(J$20:J$1048576,$D$20:$D$1048576,$G13) -> 5.8938784 | K13: =AVERAGEIFS(K$20:K$1048576,$D$20:$D$1048576,$G13) -> 6.8583333 | L13: =AVERAGEIFS(L$20:L$1048576,$D$20:$D$1048576,$G13) -> 27 | M13: =AVERAGEIFS(M$20:M$1048576,$D$20:$D$1048576,$G13) -> 71.5 | N13: =AVERAGEIFS(N$20:N$1048576,$D$20:$D$1048576,$G13) -> 52.112444 | O13: =AVERAGEIFS(O$20:O$1048576,$D$20:$D$1048576,$G13) -> 78.581543 | ... Y13: =AVERAGEIFS(Y$20:Y$1048576,$D$20:$D$1048576,$G13) -> 5276768 | Z13: =+(P13+Y13) -> 12964406 | AA13: =+Z13/'Fisico ASIG'!N13/24 -> 72.749403 | AB13: =+$AB$16*Precios!R12*Precios!P12/Precios!W12/Precios!Q12 -> 12.065574 | AC13: =+AA13-AB13 -> 60.683829
G14: =+'Fisico ASIG'!E14 -> 46143 | H14: =AVERAGEIFS(H$20:H$1048576,$D$20:$D$1048576,$G14) -> 28 | I14: =AVERAGEIFS(I$20:I$1048576,$D$20:$D$1048576,$G14) -> 5.1311705 | J14: =AVERAGEIFS(J$20:J$1048576,$D$20:$D$1048576,$G14) -> 5.7682323 | K14: =AVERAGEIFS(K$20:K$1048576,$D$20:$D$1048576,$G14) -> 6.8583333 | L14: =AVERAGEIFS(L$20:L$1048576,$D$20:$D$1048576,$G14) -> 27 | M14: =AVERAGEIFS(M$20:M$1048576,$D$20:$D$1048576,$G14) -> 71.5 | N14: =AVERAGEIFS(N$20:N$1048576,$D$20:$D$1048576,$G14) -> 99.970133 | O14: =AVERAGEIFS(O$20:O$1048576,$D$20:$D$1048576,$G14) -> 146.77674 | ... Y14: =AVERAGEIFS(Y$20:Y$1048576,$D$20:$D$1048576,$G14) -> 5125512.6 | Z14: =+(P14+Y14) -> 18830172 | AA14: =+Z14/'Fisico ASIG'!N14/24 -> 85.536663 | AB14: =+$AB$16*Precios!R13*Precios!P13/Precios!W13/Precios!Q13 -> 11.485986 | AC14: =+AA14-AB14 -> 74.050677
G15: =+'Fisico ASIG'!E15 -> 46174 | H15: =AVERAGEIFS(H$20:H$1048576,$D$20:$D$1048576,$G15) -> 28 | I15: =AVERAGEIFS(I$20:I$1048576,$D$20:$D$1048576,$G15) -> 4.9015427 | J15: =AVERAGEIFS(J$20:J$1048576,$D$20:$D$1048576,$G15) -> 5.5100951 | K15: =AVERAGEIFS(K$20:K$1048576,$D$20:$D$1048576,$G15) -> 6.8583333 | L15: =AVERAGEIFS(L$20:L$1048576,$D$20:$D$1048576,$G15) -> 27 | M15: =AVERAGEIFS(M$20:M$1048576,$D$20:$D$1048576,$G15) -> 71.5 | N15: =AVERAGEIFS(N$20:N$1048576,$D$20:$D$1048576,$G15) -> 103.10453 | O15: =AVERAGEIFS(O$20:O$1048576,$D$20:$D$1048576,$G15) -> 166.18089 | ... Y15: =AVERAGEIFS(Y$20:Y$1048576,$D$20:$D$1048576,$G15) -> 5749496.8 | Z15: =+(P15+Y15) -> 20999422 | AA15: =+Z15/'Fisico ASIG'!N15/24 -> 94.947213 | AB15: =+$AB$16*Precios!R14*Precios!P14/Precios!W14/Precios!Q14 -> 15.147541 | AC15: =+AA15-AB15 -> 79.799672
AB16: 16
E17: VALORES ECONOMICOS - PASO DIARIO | H17: VARIABLES | I17: VARIABLES | J17: VARIABLES | K17: VARIABLES | L17: VARIABLES | M17: VARIABLES | N17: VARIABLES | O17: VARIABLES | P17: VARIABLES | Q17: FIJOS | R17: FIJOS | S17: FIJOS | T17: FIJOS | U17: FIJOS | V17: FIJOS | W17: FIJOS | X17: FIJOS | Y17: FIJOS | Z17: FIJ + VAR | AA17: FIJ + VAR | AB17: FIJ + VAR | AC17: FIJ + VAR | AI17: VARIABLES | AJ17: FIJOS | AK17: FIJOS | AL17: VARIABLES | AM17: FIJOS | AN17: VARIABLES | AO17: ADICIONALES Fondo Fiduciario | AP17: ADICIONALES Transporte | AQ17: ADICIONALES Costo Combustible
H18: usd/MWh | I18: usd/MWh | J18: usd/MWh | K18: usd/MWh | L18: usd/MWh | M18: usd/MWh | N18: usd/MWh | O18: usd/MWh | P18: usd/dia | Q18: usd/MW mes | R18: usd/MW mes | S18: usd/MW mes | T18: usd/MW mes | U18: usd/MW mes | V18: usd/MW mes | W18: usd/MW mes | X18: usd/MW mes | Y18: =+P18 -> usd/dia | Z18: =+Y18 -> usd/dia | AA18: usd/Mwh | AB18: usd/Mwh | AC18: usd/Mwh | AI18: $/MWh | AJ18: $/MW mes | AK18: K | AL18: usd/MWh | AM18: usd/MW mes | AN18: usd/MWh | AO18: usd/MWh | AP18: usd/MWh | AQ18: usd/MWh
A19: TC fin de mes | B19: TC quincena | C19: AÑO | D19: MES | E19: # dias/mes | F19: TIPO dia | G19: DIA | H19: YACYRETA | I19: SALTO GRANDE | J19: HIDRO NAC Resto | K19: HIDRO COM CONCESION | L19: NUCLEAR | M19: PPA RENOV | N19: PPA TERM | O19: IMPORTACION | P19: VAR ASIG | Q19: YACYRETA | R19: SALTO GRANDE | S19: HIDRO NAC Resto | T19: HIDRO COM CONCESION | U19: NUCLEAR | V19: PPA RENOV | W19: PPA TERM | X19: IMPORTACION | Y19: FIJOS ASIG | Z19: SUMA ASIG | AA19: MONO | AB19: POT | AC19: ENER | AD19: ADIC | AI19: SALTO GRANDE | AJ19: SALTO GRANDE | AK19: SALTO GRANDE | AL19: HIDRO NAC | AM19: HIDRO NAC | AN19: PPA TERM | AO19: TER TOTAL | AP19: TER TOTAL | AQ19: TER TOTAL
A20: 1443 | B20: 1425.667 | C20: =YEAR(G20) -> 2025 | D20: =+'Fisico ASIG'!B20 -> 45931 | E20: 31 | F20: mié. | G20: 45931 | H20: 28 | I20: =AI20/A20 -> 4.6604297 | J20: =+AL20/A20 -> 5.8474012 | L20: 27 | M20: 71.5 | N20: =+AN20+AO20 -> 36.081407 | O20: 29.338123 | P20: =SUMPRODUCT(H20:O20,'Fisico ASIG'!F20:M20)*24 -> 7228969.7 | Q20: 0 | R20: =+AJ20*AK20/A20 -> 5340.3962 | S20: =+AM20/A20 -> 1548.8565 | U20: 18000 | V20: 0 | W20: 21900 | X20: 0 | Y20: =SUMPRODUCT(Q20:X20,'Fisico ASIG'!O20:V20)/E20 -> 4835534.9 | Z20: =+(P20+Y20) -> 12064505 | AA20: =+Z20/'Fisico ASIG'!N20/24 -> 61.946815 | AB20: =+$AB$16*375/0.52/730 -> 15.806112 | AC20: =+AA20-AB20 -> 46.140703 | AD20: 10 | AI20: 6725 | AJ20: 5351522 | AK20: =1.2*1.2 -> 1.44 | AL20: =4060+1627*1.4+2100 -> 8437.8 | AM20: 2235000 | AN20: 34.179304 | AO20: =0.075*0.9*(AN20-6) -> 1.902103
A21: 1443 | B21: 1425.667 | C21: =YEAR(G21) -> 2025 | D21: =+'Fisico ASIG'!B21 -> 45931 | E21: 31 | F21: jue. | G21: =+ G20+1 -> 45932 | H21: 28 | I21: =AI21/A21 -> 4.6604297 | J21: =+AL21/A21 -> 5.8474012 | L21: 27 | M21: 71.5 | N21: =+AN21+AO21 -> 36.546443 | O21: 28.82441 | P21: =SUMPRODUCT(H21:O21,'Fisico ASIG'!F21:M21)*24 -> 7182715.7 | Q21: 0 | R21: =+AJ21*AK21/A21 -> 5340.3962 | S21: =+AM21/A21 -> 1548.8565 | U21: 18000 | V21: 0 | W21: 21900 | X21: 0 | Y21: =SUMPRODUCT(Q21:X21,'Fisico ASIG'!O21:V21)/E21 -> 4867222.9 | Z21: =+(P21+Y21) -> 12049939 | AA21: =+Z21/'Fisico ASIG'!N21/24 -> 60.116829 | AB21: =+$AB$16*375/0.52/730 -> 15.806112 | AC21: =+AA21-AB21 -> 44.310717 | AI21: 6725 | AJ21: 5351522 | AK21: =1.2*1.2 -> 1.44 | AL21: =4060+1627*1.4+2100 -> 8437.8 | AM21: 2235000 | AN21: 34.614935 | AO21: =0.075*0.9*(AN21-6) -> 1.9315081
A22: 1443 | B22: 1425.667 | C22: =YEAR(G22) -> 2025 | D22: =+'Fisico ASIG'!B22 -> 45931 | E22: 31 | F22: vie. | G22: =+ G21+1 -> 45933 | H22: 28 | I22: =AI22/A22 -> 4.6604297 | J22: =+AL22/A22 -> 5.8474012 | L22: 27 | M22: 71.5 | N22: =+AN22+AO22 -> 36.06404 | O22: 30.095803 | P22: =SUMPRODUCT(H22:O22,'Fisico ASIG'!F22:M22)*24 -> 7113038.1 | Q22: 0 | R22: =+AJ22*AK22/A22 -> 5340.3962 | S22: =+AM22/A22 -> 1548.8565 | U22: 18000 | V22: 0 | W22: 21900 | X22: 0 | Y22: =SUMPRODUCT(Q22:X22,'Fisico ASIG'!O22:V22)/E22 -> 4929643.6 | Z22: =+(P22+Y22) -> 12042682 | AA22: =+Z22/'Fisico ASIG'!N22/24 -> 58.649 | AB22: =+$AB$16*375/0.52/730 -> 15.806112 | AC22: =+AA22-AB22 -> 42.842888 | AI22: 6725 | AJ22: 5351522 | AK22: =1.2*1.2 -> 1.44 | AL22: =4060+1627*1.4+2100 -> 8437.8 | AM22: 2235000 | AN22: 34.163035 | AO22: =0.075*0.9*(AN22-6) -> 1.9010049
A23: 1443 | B23: 1425.667 | C23: =YEAR(G23) -> 2025 | D23: =+'Fisico ASIG'!B23 -> 45931 | E23: 31 | F23: sáb. | G23: =+ G22+1 -> 45934 | H23: 28 | I23: =AI23/A23 -> 4.6604297 | J23: =+AL23/A23 -> 5.8474012 | L23: 27 | M23: 71.5 | N23: =+AN23+AO23 -> 38.065209 | O23: 28.443739 | P23: =SUMPRODUCT(H23:O23,'Fisico ASIG'!F23:M23)*24 -> 6948831 | Q23: 0 | R23: =+AJ23*AK23/A23 -> 5340.3962 | S23: =+AM23/A23 -> 1548.8565 | U23: 18000 | V23: 0 | W23: 21900 | X23: 0 | Y23: =SUMPRODUCT(Q23:X23,'Fisico ASIG'!O23:V23)/E23 -> 5276855.4 | Z23: =+(P23+Y23) -> 12225686 | AA23: =+Z23/'Fisico ASIG'!N23/24 -> 61.22392 | AB23: =+$AB$16*375/0.52/730 -> 15.806112 | AC23: =+AA23-AB23 -> 45.417808 | AI23: 6725 | AJ23: 5351522 | AK23: =1.2*1.2 -> 1.44 | AL23: =4060+1627*1.4+2100 -> 8437.8 | AM23: 2235000 | AN23: 36.037666 | AO23: =0.075*0.9*(AN23-6) -> 2.0275425
A24: 1443 | B24: 1425.667 | C24: =YEAR(G24) -> 2025 | D24: =+'Fisico ASIG'!B24 -> 45931 | E24: 31 | F24: dom. | G24: =+ G23+1 -> 45935 | H24: 28 | I24: =AI24/A24 -> 4.6604297 | J24: =+AL24/A24 -> 5.8474012 | L24: 27 | M24: 71.5 | N24: =+AN24+AO24 -> 36.794739 | O24: 28.623559 | P24: =SUMPRODUCT(H24:O24,'Fisico ASIG'!F24:M24)*24 -> 5992713.6 | Q24: 0 | R24: =+AJ24*AK24/A24 -> 5340.3962 | S24: =+AM24/A24 -> 1548.8565 | U24: 18000 | V24: 0 | W24: 21900 | X24: 0 | Y24: =SUMPRODUCT(Q24:X24,'Fisico ASIG'!O24:V24)/E24 -> 5333649.1 | Z24: =+(P24+Y24) -> 11326363 | AA24: =+Z24/'Fisico ASIG'!N24/24 -> 63.180646 | AB24: =+$AB$16*375/0.52/730 -> 15.806112 | AC24: =+AA24-AB24 -> 47.374535 | AI24: 6725 | AJ24: 5351522 | AK24: =1.2*1.2 -> 1.44 | AL24: =4060+1627*1.4+2100 -> 8437.8 | AM24: 2235000 | AN24: 34.847531 | AO24: =0.075*0.9*(AN24-6) -> 1.9472083
A25: 1443 | B25: 1425.667 | C25: =YEAR(G25) -> 2025 | D25: =+'Fisico ASIG'!B25 -> 45931 | E25: 31 | F25: lun. | G25: =+ G24+1 -> 45936 | H25: 28 | I25: =AI25/A25 -> 4.6604297 | J25: =+AL25/A25 -> 5.8474012 | L25: 27 | M25: 71.5 | N25: =+AN25+AO25 -> 37.169232 | O25: 28.337218 | P25: =SUMPRODUCT(H25:O25,'Fisico ASIG'!F25:M25)*24 -> 7060630.4 | Q25: 0 | R25: =+AJ25*AK25/A25 -> 5340.3962 | S25: =+AM25/A25 -> 1548.8565 | U25: 18000 | V25: 0 | W25: 21900 | X25: 0 | Y25: =SUMPRODUCT(Q25:X25,'Fisico ASIG'!O25:V25)/E25 -> 5453912.5 | Z25: =+(P25+Y25) -> 12514543 | AA25: =+Z25/'Fisico ASIG'!N25/24 -> 61.080366 | AB25: =+$AB$16*375/0.52/730 -> 15.806112 | AC25: =+AA25-AB25 -> 45.274254 | AI25: 6725 | AJ25: 5351522 | AK25: =1.2*1.2 -> 1.44 | AL25: =4060+1627*1.4+2100 -> 8437.8 | AM25: 2235000 | AN25: 35.198344 | AO25: =0.075*0.9*(AN25-6) -> 1.9708882
