Workbook

Sheet PRECIOS ACUM
A1: PRECIOS ESTIMADOS DE ENERGIA y POTENCIA x MERCADO | G1: MERCADO SPOT | J1: MATE TOTAL (Hi + Ren + Tér) | M1: GEN ASIGNADA
A2: Incluye CVP y estimación de renta marginal en base a datos operativos
A3: Incluye estimación de costos variables y fijos de la generación asignada | G3: Mercado asociado a Grandes Usuarios y demanda | J3: Mercado a término de Energía | M3: Mercado asociado a demanda estacionalizada | U3: 45962
A4: No incluye costos de servicios adicionales ni de transporte en AT/DT | G4: estacionalizada no cubierta por la generación asignada | J4: Generación asociada al MATE | M4: (Res/NO Res) cubierta por la generación asignada | U4: 45992
A5: No incluye contratos MATE - MATP a ser transaccionados | U5: 46023
A6: Datos provisorios a confirmar con la salida del DTE | G6: POT MEDIA PERIODO | H6: =+VLOOKUP($B$7,'Fisico SPOT MAT'!$G$7:$M$21,7,FALSE) -> 3338.64 | I6: MW med | J6: POT MEDIA PERIODO | K6: =+VLOOKUP($B$7,'Fisico SPOT MAT'!$G$7:$AC$21,23,FALSE) -> 2370.92 | L6: MW med | M6: POT MEDIA PERIODO | N6: =+VLOOKUP($B$7,'Fisico ASIG'!$E$8:$W$20,10,FALSE) -> 9372.16 | O6: MW med | U6: 46054
A7: VALORES ACUMULADO MES | B7: 46296 | C7: =+IF(MONTH(B7)=MONTH(MAX('Mono SPOT MAT'!G24:G1048576)),"Análisis hasta:","") -> Análisis hasta: | D7: =+IF(MONTH(B7)=MONTH(MAX('Mono SPOT MAT'!G24:G1048576)),MAX('Mono SPOT MAT'!G24:G1048576),"") -> 46320 | G7: Costo Marginal Medio | H7: =+VLOOKUP($B$7,Precios!$D$7:$N$20,2,FALSE) -> 35.516 | I7: usd/MWh | U7: 46082
C8: Días del mes: | D8: =+EDATE(B7,1)-B7 -> 31 | G8: MERCADO SPOT [usd/MWh] | H8: =+B7 -> 46296 | I8: Precio Medio Nov-25 a Sep-26 | J8: MERCADO MATE [usd/MWh] | K8: =+$B$7 -> 46296 | L8: =+I8 -> Precio Medio Nov-25 a Sep-26 | M8: MERCADO ASIGNADO [usd/MWh] | N8: =+H8 -> 46296 | O8: =+I8 -> Precio Medio Nov-25 a Sep-26 | U8: 46113
G9: ENERGIA | H9: =+VLOOKUP($B$7,Precios!$D$7:$N$22,3,FALSE) -> 38.737644 | I9: 80.653853 | J9: ENERGIA | K9: =+VLOOKUP($B$7,'Mono SPOT MAT'!$G$8:$AC$21,23,FALSE) -> 63.852513 | L9: 61.706548 | M9: ENERGIA | N9: =+VLOOKUP($B$7,Precios!$D$7:$N$20,6,FALSE) -> 42.519676 | O9: 59.881156 | U9: 46143
G10: POTENCIA | H10: =+VLOOKUP($B$7,Precios!$D$7:$AC$20,18,FALSE)-H9 -> 8.965279 | I10: 9.9255955 | J10: =G10 -> POTENCIA | K10: =H10 -> 8.965279 | L10: 9.9255955 | M10: POTENCIA | N10: =+VLOOKUP($B$7,Precios!$D$7:$N$20,5,FALSE)-N9 -> 12.315987 | O10: 14.260308 | U10: 46174
G11: Servicios | H11: =+VLOOKUP(H8,Precios!$D$7:$AA$20,23,FALSE) -> 4.0558175 | I11: 5.7429044 | J11: =G11 -> Servicios | K11: =H11 -> 4.0558175 | L11: =+I11 -> 5.7429044 | M11: Servicios | N11: =+H11 -> 4.0558175 | O11: =+I11 -> 5.7429044 | U11: 46204
G12: Transporte | H12: =+VLOOKUP(H8,Precios!$D$7:$AA$20,24,FALSE) -> 6.3384833 | I12: 6.0284379 | J12: =G12 -> Transporte | K12: =H12 -> 6.3384833 | L12: =+I12 -> 6.0284379 | M12: Transporte | N12: =+H12 -> 6.3384833 | O12: =+I12 -> 6.0284379 | U12: 46235
G13: Monómico simulado Mercado Spot para FC y HRP | H13: =+SUM(H9:H12) -> 58.097224 | I13: =+SUM(I9:I12) -> 102.35079 | J13: Monómico Mercado MAT | K13: =+SUM(K9:K12) -> 83.212093 | L13: =+SUM(L9:L12) -> 83.403486 | M13: Monómico de Costo de la Generación Asignada | N13: =+SUM(N9:N12) -> 65.229964 | O13: =+SUM(O9:O12) -> 85.912807 | U13: 46266
U14: 46296
G15: PRECIO MEDIO GRANDES USUARIOS MEM
H17: Mix MATE + SPOT [usd/MWh] | J17: =+$B$7 -> 46296 | K17: =+I8 -> Precio Medio Nov-25 a Sep-26
H18: ENERGIA | J18: =+(H9*1800+K9*1800)/3600 -> 51.295079 | K18: =+(I9*1800+L9*2000)/3800 -> 70.681588
H19: POTENCIA | J19: =+H10 -> 8.965279 | K19: =+I10 -> 9.9255955
H20: Servicios | J20: =+H11 -> 4.0558175 | K20: =+I11 -> 5.7429044
H21: Transporte | J21: =+H12 -> 6.3384833 | K21: =+I12 -> 6.0284379
H22: MONO GU | J22: =+SUM(J18:J21) -> 70.654658 | K22: =+SUM(K18:K21) -> 92.378525
G24: ANEXO TÉRMICO
G26: Generación Térmica del Mercado SPOT | H26: =+$B$7 -> 46296 | J26: Generación Térmica asociada al MAT | K26: =+$B$7 -> 46296
G27: POT MEDIA | H27: =+VLOOKUP($B$7,'Fisico SPOT MAT'!$G$7:$AA$21,2,FALSE) -> 2777.4 | I27: MW med | J27: POT MEDIA | K27: =+VLOOKUP($B$7,'Fisico SPOT MAT'!$G$7:$AA$21,14,FALSE) -> 650 | L27: MW med
G28: ENERGIA | H28: =+VLOOKUP($B$7,'Mono SPOT MAT'!$G$7:$M$21,2,FALSE) -> 37.872117 | I28: usd/MWh | J28: ENERGIA | K28: =+VLOOKUP($B$7,Precios!$D$7:$N$20,8,FALSE) -> 80 | L28: usd/MWh
G29: POTENCIA | H29: =+VLOOKUP($B$7,Precios!$D$7:$N$20,4,FALSE) -> 14.4 | I29: usd/MWhrp | J29: POTENCIA | K29: =+IF(K27=0,0,VLOOKUP($B$7,Precios!$D$7:$N$20,7,FALSE)) -> 14.4 | L29: usd/MWhrp
G30: MONO E + P para FC | H30: =+VLOOKUP($B$7,Precios!$D$7:$AC$20,19,FALSE) -> 46.837396 | I30: usd/MWh | J30: MONO MAT | K30: =+IF(K27=0,0,+H30-H28+K28) -> 88.965279 | L30: usd/MWh

Sheet Precios
B1: PRECIOS ESTIMADOS DE ENERGIA y POTENCIA x MERCADO
B2: Incluye CVP y estimación de renta marginal en base a datos operativos
B3: Incluye estimación de costos variables y fijos de la generación asignada
B6: VALORES ECONOMICOS - ACUMULADO MES | E6: usd/MWh | F6: usd/MWh | G6: usd/MWhrp | H6: usd/MWh | I6: usd/MWh | J6: usd/MWhrp | K6: usd/MWh | L6: usd/MWh | T6: usd/MWh | U6: usd/MWh | X6: usd/MWh | Z6: usd/MWh | AA6: usd/MWh
C7: Cant días: | D7: MES | E7: CMg | F7: ENER SPOT | G7: POT SPOT | H7: MONO ASIG | I7: ENER ASIG | J7: POT ASIG | K7: TÉRMICO MATE | L7: total MATE | N7: POT SPOT | P7: HRP | Q7: HMES | R7: Factor Potencia | S7: FC SPOT | T7: POT SPOT | U7: MONO SPOT | V7: TÉRMICO SPOT | W7: FC Asignado | X7: POT asig | Z7: SERVICIOS | AA7: Transporte
C8: =+EDATE(D8,1)-D8 -> 30 | D8: 45962 | E8: =AVERAGEIFS($E$25:$E$1048576,$B$25:$B$1048576,D8) -> 32.334184 | F8: =+SUMPRODUCT(F56:F85,'Fisico SPOT MAT'!M56:M85)/SUM('Fisico SPOT MAT'!M56:M85) -> 35.782032 | G8: =AVERAGEIFS($G$25:$G$1048576,$B$25:$B$1048576,D8) -> 14.4 | H8: =+SUMPRODUCT(H56:H85,'Fisico ASIG'!$P$56:$P$85)/SUM('Fisico ASIG'!$P$56:$P$85) -> 62.0728 | I8: =+SUMPRODUCT(I56:I85,'Fisico ASIG'!$P$56:$P$85)/SUM('Fisico ASIG'!$P$56:$P$85) -> 47.657627 | J8: =AVERAGEIFS($J$25:$J$1048576,$B$25:$B$1048576,D8) -> 14.4 | N8: =AVERAGEIFS($N$25:$N$1048576,$B$25:$B$1048576,D8) -> 11.53116 | P8: ='Fisico SPOT MAT'!E8 -> 348 | Q8: =+C8*24 -> 720 | R8: =AVERAGEIFS(R$24:R$1048576,$B$24:$B$1048576,$D8) -> 0.9 | S8: 0.75 | T8: =+G8*P8/Q8/S8 -> 9.28 | U8: =+T8+F8 -> 45.062032 | V8: =+T8+'Mono SPOT MAT'!H8 -> 47.062843 | W8: 0.52 | X8: =+J8*P8/Q8/W8 -> 13.384615 | Z8: 5.8 | AA8: 5.7
C9: =+EDATE(D9,1)-D9 -> 31 | D9: 45992 | E9: =AVERAGEIFS($E$25:$E$1048576,$B$25:$B$1048576,D9) -> 40.553132 | F9: =+SUMPRODUCT(F86:F116,'Fisico SPOT MAT'!M86:M116)/SUM('Fisico SPOT MAT'!M86:M116) -> 40.399389 | G9: =AVERAGEIFS($G$25:$G$1048576,$B$25:$B$1048576,D9) -> 17.6 | H9: =+SUMPRODUCT(H86:H116,'Fisico ASIG'!$P$86:$P$116)/SUM('Fisico ASIG'!$P$86:$P$116) -> 63.788293 | I9: =+SUMPRODUCT(I86:I116,'Fisico ASIG'!$P$86:$P$116)/SUM('Fisico ASIG'!$P$86:$P$116) -> 46.31931 | J9: =AVERAGEIFS($J$25:$J$1048576,$B$25:$B$1048576,D9) -> 17.6 | N9: =AVERAGEIFS($N$25:$N$1048576,$B$25:$B$1048576,D9) -> 15.772536 | P9: ='Fisico SPOT MAT'!E9 -> 384 | Q9: =+C9*24 -> 744 | R9: =AVERAGEIFS(R$24:R$1048576,$B$24:$B$1048576,$D9) -> 1.1 | S9: 0.75 | T9: =+G9*P9/Q9/S9 -> 12.111828 | U9: =+T9+F9 -> 52.511217 | V9: =+T9+'Mono SPOT MAT'!H9 -> 54.271807 | W9: 0.52 | X9: =+J9*P9/Q9/W9 -> 17.468983 | Z9: 3.9467458 | AA9: 5.2611399
C10: =+EDATE(D10,1)-D10 -> 31 | D10: 46023 | E10: =AVERAGEIFS($E$25:$E$1048576,$B$25:$B$1048576,D10) -> 55.612597 | F10: =+SUMPRODUCT(F117:F147,'Fisico SPOT MAT'!M117:M147)/SUM('Fisico SPOT MAT'!M117:M147) -> 42.573442 | G10: =AVERAGEIFS($G$25:$G$1048576,$B$25:$B$1048576,D10) -> 17.6 | H10: =+SUMPRODUCT(H117:H147,'Fisico ASIG'!$P$117:$P$147)/SUM('Fisico ASIG'!$P$117:$P$147) -> 65.981465 | I10: =+SUMPRODUCT(I117:I147,'Fisico ASIG'!$P$117:$P$147)/SUM('Fisico ASIG'!$P$117:$P$147) -> 48.421499 | J10: =AVERAGEIFS($J$25:$J$1048576,$B$25:$B$1048576,D10) -> 17.6 | N10: =AVERAGEIFS($N$25:$N$1048576,$B$25:$B$1048576,D10) -> 15.674033 | P10: ='Fisico SPOT MAT'!E10 -> 386 | Q10: =+C10*24 -> 744 | R10: =AVERAGEIFS(R$24:R$1048576,$B$24:$B$1048576,$D10) -> 1.1 | S10: 0.75 | T10: =+G10*P10/Q10/S10 -> 12.17491 | U10: =+T10+F10 -> 54.748353 | V10: =+T10+'Mono SPOT MAT'!H10 -> 56.984422 | W10: 0.60886856 | X10: =+J10*P10/Q10/W10 -> 14.996969 | Z10: 3.9 | AA10: 5.4
C11: =+EDATE(D11,1)-D11 -> 28 | D11: 46054 | E11: =AVERAGEIFS($E$25:$E$1048576,$B$25:$B$1048576,D11) -> 52.514713 | F11: =+SUMPRODUCT(F148:F175,'Fisico SPOT MAT'!M148:M175)/SUM('Fisico SPOT MAT'!M148:M175) -> 42.909911 | G11: =AVERAGEIFS($G$25:$G$1048576,$B$25:$B$1048576,D11) -> 17.6 | H11: =+SUMPRODUCT(H148:H175,'Fisico ASIG'!$N$148:$N$175)/SUM('Fisico ASIG'!$N$148:$N$175) -> 73.131269 | I11: =+SUMPRODUCT(I148:I175,'Fisico ASIG'!$N$148:$N$175)/SUM('Fisico ASIG'!$N$148:$N$175) -> 56.208193 | J11: =AVERAGEIFS($J$25:$J$1048576,$B$25:$B$1048576,D11) -> 17.6 | N11: =AVERAGEIFS($N$25:$N$1048576,$B$25:$B$1048576,D11) -> 15.854857 | P11: ='Fisico SPOT MAT'!E11 -> 336 | Q11: =+C11*24 -> 672 | R11: =AVERAGEIFS(R$24:R$1048576,$B$24:$B$1048576,$D11) -> 1.1 | S11: 0.75 | T11: =+G11*P11/Q11/S11 -> 11.733333 | U11: =+T11+F11 -> 54.643244 | V11: =+T11+'Mono SPOT MAT'!H11 -> 57.10384 | W11: 0.60935733 | X11: =+J11*P11/Q11/W11 -> 14.441444 | Z11: 4.2415654 | AA11: 5.5316882
C12: =+EDATE(D12,1)-D12 -> 31 | D12: 46082 | E12: =AVERAGEIFS($E$25:$E$1048576,$B$25:$B$1048576,D12) -> 62.286214 | F12: =+SUMPRODUCT(F176:F206,'Fisico SPOT MAT'!M176:M206)/SUM('Fisico SPOT MAT'!M176:M206) -> 45.274491 | G12: =AVERAGEIFS($G$25:$G$1048576,$B$25:$B$1048576,D12) -> 14.4 | H12: =+SUMPRODUCT(H176:H206,'Fisico ASIG'!$N$176:$N$206)/SUM('Fisico ASIG'!$N$176:$N$206) -> 71.173352 | I12: =+SUMPRODUCT(I176:I206,'Fisico ASIG'!$N$176:$N$206)/SUM('Fisico ASIG'!$N$176:$N$206) -> 58.645315 | J12: =AVERAGEIFS($J$25:$J$1048576,$B$25:$B$1048576,D12) -> 14.4 | N12: =AVERAGEIFS($N$25:$N$1048576,$B$25:$B$1048576,D12) -> 15.212011 | P12: ='Fisico SPOT MAT'!E12 -> 374 | Q12: =+C12*24 -> 744 | R12: =AVERAGEIFS(R$24:R$1048576,$B$24:$B$1048576,$D12) -> 0.9 | S12: 0.82756876 | T12: =+G12*P12/Q12/S12 -> 8.7469586 | U12: =+T12+F12 -> 54.021449 | V12: =+T12+'Mono SPOT MAT'!H12 -> 55.751221 | W12: 0.57780079 | X12: =+J12*P12/Q12/W12 -> 12.528037 | Z12: 4.3271912 | AA12: 6.3890889
C13: =+'Mono SPOT MAT'!F13 -> 30 | D13: 46113 | E13: =AVERAGEIFS($E$25:$E$1048576,$B$25:$B$1048576,D13) -> 86.168556 | F13: =+SUMPRODUCT(F207:F236,'Fisico SPOT MAT'!M207:M236)/SUM('Fisico SPOT MAT'!M207:M236) -> 51.723013 | G13: =AVERAGEIFS($G$25:$G$1048576,$B$25:$B$1048576,D13) -> 14.4 | H13: =+SUMPRODUCT(H207:H236,'Fisico ASIG'!$N$207:$N$236)/SUM('Fisico ASIG'!$N$207:$N$236) -> 72.749403 | I13: =+SUMPRODUCT(I207:I236,'Fisico ASIG'!$N$207:$N$236)/SUM('Fisico ASIG'!$N$207:$N$236) -> 59.782581 | J13: =AVERAGEIFS($J$25:$J$1048576,$B$25:$B$1048576,D13) -> 14.4 | N13: =AVERAGEIFS($N$25:$N$1048576,$B$25:$B$1048576,D13) -> 15.093951 | P13: 368 | Q13: =30*24 -> 720 | R13: =AVERAGEIFS(R$24:R$1048576,$B$24:$B$1048576,$D13) -> 0.9 | S13: 0.82756876 | T13: =+G13*P13/Q13/S13 -> 8.8935208 | U13: =+T13+F13 -> 60.616534 | V13: =+T13+'Mono SPOT MAT'!H13 -> 63.092365 | W13: 0.56760247 | X13: =+J13*P13/Q13/W13 -> 12.966822 | Z13: 4.3350157 | AA13: 6.9556699
C14: =+'Mono SPOT MAT'!F14 -> 31 | D14: 46143 | E14: =AVERAGEIFS($E$25:$E$1048576,$B$25:$B$1048576,D14) -> 188.32262 | F14: =+SUMPRODUCT(F237:F267,'Fisico SPOT MAT'!M237:M267)/SUM('Fisico SPOT MAT'!M237:M267) -> 117.98009 | G14: =AVERAGEIFS($G$25:$G$1048576,$B$25:$B$1048576,D14) -> 14.4 | H14: =+SUMPRODUCT(H237:H267,'Fisico ASIG'!$N$237:$N$267)/SUM('Fisico ASIG'!$N$237:$N$267) -> 85.537689 | I14: =+SUMPRODUCT(I237:I267,'Fisico ASIG'!$N$237:$N$267)/SUM('Fisico ASIG'!$N$237:$N$267) -> 74.380304 | J14: =AVERAGEIFS($J$25:$J$1048576,$B$25:$B$1048576,D14) -> 14.4 | N14: =AVERAGEIFS($N$25:$N$1048576,$B$25:$B$1048576,D14) -> 15.324438 | P14: 362 | Q14: =31*24 -> 744 | R14: =AVERAGEIFS(R$24:R$1048576,$B$24:$B$1048576,$D14) -> 0.9 | S14: 0.82756876 | T14: =+G14*P14/Q14/S14 -> 8.4663075 | U14: =+T14+F14 -> 126.4464 | V14: =+T14+'Mono SPOT MAT'!H14 -> 122.59214 | W14: 0.62796537 | X14: =+J14*P14/Q14/W14 -> 11.157385 | Z14: 6.2696035 | AA14: 6.2922056
C15: =+'Mono SPOT MAT'!F15 -> 30 | D15: 46174 | E15: =AVERAGEIFS($E$25:$E$1048576,$B$25:$B$1048576,D15) -> 202.55727 | F15: =+SUMPRODUCT(F268:F297,'Fisico SPOT MAT'!M267:M296)/SUM('Fisico SPOT MAT'!M268:M296) -> 176.47464 | G15: =AVERAGEIFS($G$25:$G$1048576,$B$25:$B$1048576,D15) -> 17.6 | H15: =+SUMPRODUCT(H268:H297,'Fisico ASIG'!$N$268:$N$297)/SUM('Fisico ASIG'!$N$268:$N$297) -> 97.092179 | I15: =+SUMPRODUCT(I268:I297,'Fisico ASIG'!$N$268:$N$297)/SUM('Fisico ASIG'!$N$268:$N$297) -> 83.305327 | J15: =AVERAGEIFS($J$25:$J$1048576,$B$25:$B$1048576,D15) -> 17.6 | K15: =+SUMPRODUCT(K268:K297,'Fisico SPOT MAT'!T268:T297)/SUM('Fisico SPOT MAT'!T268:T297) -> 70 | L15: =+'Mono SPOT MAT'!AC15 -> 62.568231 | N15: =AVERAGEIFS($N$25:$N$1048576,$B$25:$B$1048576,D15) -> 16.434821 | P15: 378 | Q15: =30*24 -> 720 | R15: =AVERAGEIFS(R$24:R$1048576,$B$24:$B$1048576,$D15) -> 1.1 | S15: 0.82756876 | T15: =+G15*P15/Q15/S15 -> 11.165235 | U15: =+T15+F15 -> 187.63987 | V15: =+T15+'Mono SPOT MAT'!H15 -> 182.57927 | W15: 0.67020374 | X15: =+J15*P15/Q15/W15 -> 13.786852 | Z15: 8.9 | AA15: 5.8551075
C16: =+'Mono SPOT MAT'!F16 -> 31 | D16: 46204 | E16: =AVERAGEIFS($E$25:$E$1048576,$B$25:$B$1048576,D16) -> 154.21003 | F16: =+SUMPRODUCT(F298:F328,'Fisico SPOT MAT'!M298:M328)/SUM('Fisico SPOT MAT'!M298:M328) -> 143.1864 | G16: =AVERAGEIFS($G$25:$G$1048576,$B$25:$B$1048576,D16) -> 17.6 | H16: =+SUMPRODUCT(H298:H328,'Fisico ASIG'!$N$298:$N$328)/SUM('Fisico ASIG'!$N$298:$N$328) -> 79.568531 | I16: =+SUMPRODUCT(I298:I328,'Fisico ASIG'!$N$298:$N$328)/SUM('Fisico ASIG'!$N$298:$N$328) -> 65.431018 | J16: =AVERAGEIFS($J$25:$J$1048576,$B$25:$B$1048576,D16) -> 17.6 | K16: =+SUMPRODUCT(K298:K328,'Fisico SPOT MAT'!T298:T328)/SUM('Fisico SPOT MAT'!T298:T328) -> 80 | L16: =+'Mono SPOT MAT'!AC16 -> 66.471181 | N16: =AVERAGEIFS($N$25:$N$1048576,$B$25:$B$1048576,D16) -> 16.293318 | P16: 386 | Q16: =31*24 -> 744 | R16: =AVERAGEIFS(R$24:R$1048576,$B$24:$B$1048576,$D16) -> 1.1 | S16: 0.82756876 | T16: =+G16*P16/Q16/S16 -> 11.033745 | U16: =+T16+F16 -> 154.22014 | V16: =+T16+'Mono SPOT MAT'!H16 -> 153.58662 | W16: 0.64588324 | X16: =+J16*P16/Q16/W16 -> 14.137513 | Z16: 8.3474685 | AA16: 5.9359257
C17: =+'Mono SPOT MAT'!F17 -> 31 | D17: 46235 | E17: =AVERAGEIFS($E$25:$E$1048576,$B$25:$B$1048576,D17) -> 141.37171 | F17: =+SUMPRODUCT(F329:F359,'Fisico SPOT MAT'!M329:M359)/SUM('Fisico SPOT MAT'!M329:M359) -> 133.28858 | G17: =AVERAGEIFS($G$25:$G$1048576,$B$25:$B$1048576,D17) -> 17.6 | H17: =+SUMPRODUCT(H329:H359,'Fisico ASIG'!$N329:$N$359)/SUM('Fisico ASIG'!$N329:$N$359) -> 80.768274 | I17: =+SUMPRODUCT(I329:I359,'Fisico ASIG'!$N329:$N$359)/SUM('Fisico ASIG'!$N329:$N359) -> 66.869884 | J17: =AVERAGEIFS($J$25:$J$1048576,$B$25:$B$1048576,D17) -> 17.6 | K17: =+SUMPRODUCT(K329:K359,'Fisico SPOT MAT'!T329:T359)/SUM('Fisico SPOT MAT'!T329:T359) -> 80 | L17: =+'Mono SPOT MAT'!AC17 -> 64.918897 | N17: =AVERAGEIFS($N$25:$N$1048576,$B$25:$B$1048576,D17) -> 16.36389 | P17: 374 | Q17: =31*24 -> 744 | R17: =AVERAGEIFS(R$24:R$1048576,$B$24:$B$1048576,$D17) -> 1.1 | S17: 0.83332239 | T17: =+G17*P17/Q17/S17 -> 10.616914 | U17: =+T17+F17 -> 143.9055 | V17: =+T17+'Mono SPOT MAT'!H17 -> 145.2139 | W17: 0.63657099 | X17: =+J17*P17/Q17/W17 -> 13.89839 | Z17: 7.9673582 | AA17: 6.3619912
C18: =+'Mono SPOT MAT'!F18 -> 30 | D18: 46266 | E18: =AVERAGEIFS($E$25:$E$1048576,$B$25:$B$1048576,D18) -> 62.269959 | F18: =+SUMPRODUCT(F360:F389,'Fisico SPOT MAT'!M360:M389)/SUM('Fisico SPOT MAT'!M360:M389) -> 71.50995 | G18: =AVERAGEIFS($G$25:$G$1048576,$B$25:$B$1048576,D18) -> 14.4 | H18: =+SUMPRODUCT(H360:H389,'Fisico ASIG'!$N$360:$N389)/SUM('Fisico ASIG'!$N$360:$N389) -> 63.540031 | I18: =+SUMPRODUCT(I360:I389,'Fisico ASIG'!$N360:$N$389)/SUM('Fisico ASIG'!$N360:$N389) -> 51.224044 | J18: =AVERAGEIFS($J$25:$J$1048576,$B$25:$B$1048576,D18) -> 14.4 | K18: =+SUMPRODUCT(K360:K389,'Fisico SPOT MAT'!T360:T389)/SUM('Fisico SPOT MAT'!T360:T389) -> 80 | L18: =+'Mono SPOT MAT'!AC18 -> 63.668157 | N18: =AVERAGEIFS($N$25:$N$1048576,$B$25:$B$1048576,D18) -> 15.758075 | P18: 392 | Q18: =30*24 -> 720 | R18: =AVERAGEIFS(R$24:R$1048576,$B$24:$B$1048576,$D18) -> 0.9 | S18: 0.83332239 | T18: =+G18*P18/Q18/S18 -> 9.4081235 | U18: =+T18+F18 -> 80.918073 | V18: =+T18+'Mono SPOT MAT'!H18 -> 82.972537 | W18: 0.63657099 | X18: =+J18*P18/Q18/W18 -> 12.315987 | Z18: 5.137 | AA18: 6.63
B19: =+'Mono SPOT MAT'!E19 -> días en análisis: | C19: =+'Mono SPOT MAT'!F19 -> 25 | D19: 46296 | E19: =AVERAGEIFS($E$25:$E$1048576,$B$25:$B$1048576,D19) -> 35.516 | F19: =+SUMPRODUCT(F390:F414,'Fisico SPOT MAT'!M390:M414)/SUM('Fisico SPOT MAT'!M390:M414) -> 38.737644 | G19: =AVERAGEIFS($G$25:$G$1048576,$B$25:$B$1048576,D19) -> 14.4 | H19: =+SUMPRODUCT(H390:H414,'Fisico ASIG'!$N390:$N$414)/SUM('Fisico ASIG'!$N390:$N$414) -> 54.835663 | I19: =+SUMPRODUCT(I390:I414,'Fisico ASIG'!$N390:$N$414)/SUM('Fisico ASIG'!$N390:$N414) -> 42.519676 | J19: =AVERAGEIFS($J$25:$J$1048576,$B$25:$B$1048576,D19) -> 14.4 | K19: =+SUMPRODUCT(K390:K414,'Fisico SPOT MAT'!T390:T414)/SUM('Fisico SPOT MAT'!T390:T414) -> 80 | L19: =+'Mono SPOT MAT'!AC19 -> 63.852513 | N19: =AVERAGEIFS($N$25:$N$1048576,$B$25:$B$1048576,D19) -> 15.595352 | P19: 386 | Q19: =31*24 -> 744 | R19: =AVERAGEIFS(R$24:R$1048576,$B$24:$B$1048576,$D19) -> 0.9 | S19: 0.83332239 | T19: =+G19*P19/Q19/S19 -> 8.965279 | U19: =+T19+F19 -> 47.702923 | V19: =+T19+'Mono SPOT MAT'!H19 -> 46.837396 | W19: 0.63657099 | X19: =+J19*P19/Q19/W19 -> 11.736268 | Z19: =3.5%*F19+2.7 -> 4.0558175 | AA19: =+AVERAGE(AA13:AA18) -> 6.3384833
B22: VALORES FISICOS - PASO DIARIO
E23: usd/MWh | F23: usd/MWh | G23: usd/MWhrp | H23: usd/MWh | I23: usd/MWh | J23: usd/MWhrp | K23: usd/MWh
A24: AÑO | B24: MES | C24: TIPO dia | D24: DIA | E24: CMg | F24: ENER SPOT | G24: POT SPOT | H24: MONO ASIG | I24: ENER ASIG | J24: POT ASIG | K24: ENER TERM MAT | N24: POT SPOT | R24: Factor Potencia | Y24: =$D24 -> DIA | Z24: =+E24 -> CMg | AA24: CVP | AB24: RMA
A25: =YEAR(D25) -> 2025 | B25: =DATE(A25,MONTH(D25),1) -> 45931 | C25: mié. | D25: 45931 | E25: 24.854148 | F25: =+'Mono SPOT MAT'!M25/'Fisico SPOT MAT'!M25/24 -> 29.684186 | G25: =16*R25 -> 14.4 | H25: =+'Mono ASIG'!AA25 -> 61.946815 | I25: =+H25-J25*380/730/0.52 -> 47.531641 | J25: =16*R25 -> 14.4 | N25: =+'Mono SPOT MAT'!S25/'Fisico SPOT MAT'!S25/'Fisico SPOT MAT'!E25 -> 11.3809 | R25: 0.9
A26: =YEAR(D26) -> 2025 | B26: =DATE(A26,MONTH(D26),1) -> 45931 | C26: jue. | D26: =+ D25+1 -> 45932 | E26: 27.983237 | F26: =+'Mono SPOT MAT'!M26/'Fisico SPOT MAT'!M26/24 -> 30.044257 | G26: =16*R26 -> 14.4 | H26: =+'Mono ASIG'!AA26 -> 60.116829 | I26: =+H26-J26*380/730/0.52 -> 45.701655 | J26: =16*R26 -> 14.4 | N26: =+'Mono SPOT MAT'!S26/'Fisico SPOT MAT'!S26/'Fisico SPOT MAT'!E26 -> 11.407825 | R26: 0.9
A27: =YEAR(D27) -> 2025 | B27: =DATE(A27,MONTH(D27),1) -> 45931 | C27: vie. | D27: =+ D26+1 -> 45933 | E27: 27.892877 | F27: =+'Mono SPOT MAT'!M27/'Fisico SPOT MAT'!M27/24 -> 30.691543 | G27: =16*R27 -> 14.4 | H27: =+'Mono ASIG'!AA27 -> 58.649 | I27: =+H27-J27*380/730/0.52 -> 44.233826 | J27: =16*R27 -> 14.4 | N27: =+'Mono SPOT MAT'!S27/'Fisico SPOT MAT'!S27/'Fisico SPOT MAT'!E27 -> 11.413798 | R27: 0.9
A28: =YEAR(D28) -> 2025 | B28: =DATE(A28,MONTH(D28),1) -> 45931 | C28: sáb. | D28: =+ D27+1 -> 45934 | E28: 31.530274 | F28: =+'Mono SPOT MAT'!M28/'Fisico SPOT MAT'!M28/24 -> 32.022819 | G28: =16*R28 -> 14.4 | H28: =+'Mono ASIG'!AA28 -> 61.22392 | I28: =+H28-J28*380/730/0.52 -> 46.808746 | J28: =16*R28 -> 14.4 | N28: =+'Mono SPOT MAT'!S28/'Fisico SPOT MAT'!S28/'Fisico SPOT MAT'!E28 -> 11.377526 | R28: 0.9
A29: =YEAR(D29) -> 2025 | B29: =DATE(A29,MONTH(D29),1) -> 45931 | C29: dom. | D29: =+ D28+1 -> 45935 | E29: 28.785433 | F29: =+'Mono SPOT MAT'!M29/'Fisico SPOT MAT'!M29/24 -> 31.941739 | G29: =16*R29 -> 14.4 | H29: =+'Mono ASIG'!AA29 -> 63.180646 | I29: =+H29-J29*380/730/0.52 -> 48.765472 | J29: =16*R29 -> 14.4 | N29: =+'Mono SPOT MAT'!S29/'Fisico SPOT MAT'!S29/'Fisico SPOT MAT'!E29 -> 11.37484 | R29: 0.9
A30: =YEAR(D30) -> 2025 | B30: =DATE(A30,MONTH(D30),1) -> 45931 | C30: lun. | D30: =+ D29+1 -> 45936 | E30: 31.612932 | F30: =+'Mono SPOT MAT'!M30/'Fisico SPOT MAT'!M30/24 -> 30.996048 | G30: =16*R30 -> 14.4 | H30: =+'Mono ASIG'!AA30 -> 61.080366 | I30: =+H30-J30*380/730/0.52 -> 46.665192 | J30: =16*R30 -> 14.4 | N30: =+'Mono SPOT MAT'!S30/'Fisico SPOT MAT'!S30/'Fisico SPOT MAT'!E30 -> 11.380223 | R30: 0.9
A31: =YEAR(D31) -> 2025 | B31: =DATE(A31,MONTH(D31),1) -> 45931 | C31: mar. | D31: =+ D30+1 -> 45937 | E31: 31.570178 | F31: =+'Mono SPOT MAT'!M31/'Fisico SPOT MAT'!M31/24 -> 30.784964 | G31: =16*R31 -> 14.4 | H31: =+'Mono ASIG'!AA31 -> 63.155935 | I31: =+H31-J31*380/730/0.52 -> 48.740761 | J31: =16*R31 -> 14.4 | N31: =+'Mono SPOT MAT'!S31/'Fisico SPOT MAT'!S31/'Fisico SPOT MAT'!E31 -> 11.376157 | R31: 0.9
A32: =YEAR(D32) -> 2025 | B32: =DATE(A32,MONTH(D32),1) -> 45931 | C32: mié. | D32: =+ D31+1 -> 45938 | E32: 27.96837 | F32: =+'Mono SPOT MAT'!M32/'Fisico SPOT MAT'!M32/24 -> 31.348177 | G32: =16*R32 -> 14.4 | H32: =+'Mono ASIG'!AA32 -> 65.376973 | I32: =+H32-J32*380/730/0.52 -> 50.961799 | J32: =16*R32 -> 14.4 | N32: =+'Mono SPOT MAT'!S32/'Fisico SPOT MAT'!S32/'Fisico SPOT MAT'!E32 -> 11.379375 | R32: 0.9
A33: =YEAR(D33) -> 2025 | B33: =DATE(A33,MONTH(D33),1) -> 45931 | C33: jue. | D33: =+ D32+1 -> 45939 | E33: 29.918786 | F33: =+'Mono SPOT MAT'!M33/'Fisico SPOT MAT'!M33/24 -> 30.859801 | G33: =16*R33 -> 14.4 | H33: =+'Mono ASIG'!AA33 -> 63.346287 | I33: =+H33-J33*380/730/0.52 -> 48.931114 | J33: =16*R33 -> 14.4 | N33: =+'Mono SPOT MAT'!S33/'Fisico SPOT MAT'!S33/'Fisico SPOT MAT'!E33 -> 11.37513 | R33: 0.9
A34: =YEAR(D34) -> 2025 | B34: =DATE(A34,MONTH(D34),1) -> 45931 | C34: vie. | D34: =+ D33+1 -> 45940 | E34: 28.943681 | F34: =+'Mono SPOT MAT'!M34/'Fisico SPOT MAT'!M34/24 -> 31.651831 | G34: =16*R34 -> 14.4 | H34: =+'Mono ASIG'!AA34 -> 63.163796 | I34: =+H34-J34*380/730/0.52 -> 48.748622 | J34: =16*R34 -> 14.4 | N34: =+'Mono SPOT MAT'!S34/'Fisico SPOT MAT'!S34/'Fisico SPOT MAT'!E34 -> 11.374467 | R34: 0.9
A35: =YEAR(D35) -> 2025 | B35: =DATE(A35,MONTH(D35),1) -> 45931 | C35: sáb. | D35: =+ D34+1 -> 45941 | E35: 30.423262 | F35: =+'Mono SPOT MAT'!M35/'Fisico SPOT MAT'!M35/24 -> 31.926912 | G35: =16*R35 -> 14.4 | H35: =+'Mono ASIG'!AA35 -> 62.649776 | I35: =+H35-J35*380/730/0.52 -> 48.234602 | J35: =16*R35 -> 14.4 | N35: =+'Mono SPOT MAT'!S35/'Fisico SPOT MAT'!S35/'Fisico SPOT MAT'!E35 -> 11.373415 | R35: 0.9
A36: =YEAR(D36) -> 2025 | B36: =DATE(A36,MONTH(D36),1) -> 45931 | C36: dom. | D36: =+ D35+1 -> 45942 | E36: 19.247504 | F36: =+'Mono SPOT MAT'!M36/'Fisico SPOT MAT'!M36/24 -> 32.592034 | G36: =16*R36 -> 14.4 | H36: =+'Mono ASIG'!AA36 -> 68.841525 | I36: =+H36-J36*380/730/0.52 -> 54.426351 | J36: =16*R36 -> 14.4 | N36: =+'Mono SPOT MAT'!S36/'Fisico SPOT MAT'!S36/'Fisico SPOT MAT'!E36 -> 11.366155 | R36: 0.9
A37: =YEAR(D37) -> 2025 | B37: =DATE(A37,MONTH(D37),1) -> 45931 | C37: lun. | D37: =+ D36+1 -> 45943 | E37: 28.342066 | F37: =+'Mono SPOT MAT'!M37/'Fisico SPOT MAT'!M37/24 -> 31.780016 | G37: =16*R37 -> 14.4 | H37: =+'Mono ASIG'!AA37 -> 61.633753 | I37: =+H37-J37*380/730/0.52 -> 47.218579 | J37: =16*R37 -> 14.4 | N37: =+'Mono SPOT MAT'!S37/'Fisico SPOT MAT'!S37/'Fisico SPOT MAT'!E37 -> 11.369995 | R37: 0.9
... A85: =YEAR(D85) -> 2025 | B85: =DATE(A85,MONTH(D85),1) -> 45962 | C85: dom | D85: =+ D84+1 -> 45991 | E85: 37.418409 | F85: =+'Mono SPOT MAT'!M85/'Fisico SPOT MAT'!M85/24 -> 35.166272 | G85: =16*R85 -> 14.4 | H85: =+'Mono ASIG'!AA85 -> 71.721664 | I85: =+H85-J85*380/730/0.52 -> 57.30649 | J85: =16*R85 -> 14.4 | N85: =+'Mono SPOT MAT'!S85/'Fisico SPOT MAT'!S85/'Fisico SPOT MAT'!E85 -> 11.571719 | R85: 0.9
A86: =YEAR(D86) -> 2025 | B86: =DATE(A86,MONTH(D86),1) -> 45992 | C86: lun | D86: =+ D85+1 -> 45992 | E86: 47.852748 | F86: =+'Mono SPOT MAT'!M86/'Fisico SPOT MAT'!M86/24 -> 39.212751 | G86: =16*R86 -> 17.6 | H86: =+'Mono ASIG'!AA86 -> 64.022508 | I86: =+H86-J86*384/744/0.52 -> 46.553526 | J86: =16*R86 -> 17.6 | N86: =+'Mono SPOT MAT'!S86/'Fisico SPOT MAT'!S86/'Fisico SPOT MAT'!E86 -> 15.791563 | R86: 1.1
A87: =YEAR(D87) -> 2025 | B87: =DATE(A87,MONTH(D87),1) -> 45992 | C87: mar | D87: =+ D86+1 -> 45993 | E87: 44.491079 | F87: =+'Mono SPOT MAT'!M87/'Fisico SPOT MAT'!M87/24 -> 38.655333 | G87: =16*R87 -> 17.6 | H87: =+'Mono ASIG'!AA87 -> 65.403461 | I87: =+H87-J87*384/744/0.52 -> 47.934479 | J87: =16*R87 -> 17.6 | N87: =+'Mono SPOT MAT'!S87/'Fisico SPOT MAT'!S87/'Fisico SPOT MAT'!E87 -> 15.717185 | R87: 1.1
A88: =YEAR(D88) -> 2025 | B88: =DATE(A88,MONTH(D88),1) -> 45992 | C88: mié | D88: =+ D87+1 -> 45994 | E88: 49.450391 | F88: =+'Mono SPOT MAT'!M88/'Fisico SPOT MAT'!M88/24 -> 40.563123 | G88: =16*R88 -> 17.6 | H88: =+'Mono ASIG'!AA88 -> 60.136069 | I88: =+H88-J88*384/744/0.52 -> 42.667086 | J88: =16*R88 -> 17.6 | N88: =+'Mono SPOT MAT'!S88/'Fisico SPOT MAT'!S88/'Fisico SPOT MAT'!E88 -> 15.603869 | R88: 1.1
A89: =YEAR(D89) -> 2025 | B89: =DATE(A89,MONTH(D89),1) -> 45992 | C89: jue | D89: =+ D88+1 -> 45995 | E89: 48.991631 | F89: =+'Mono SPOT MAT'!M89/'Fisico SPOT MAT'!M89/24 -> 41.329226 | G89: =16*R89 -> 17.6 | H89: =+'Mono ASIG'!AA89 -> 58.429944 | I89: =+H89-J89*384/744/0.52 -> 40.960961 | J89: =16*R89 -> 17.6 | N89: =+'Mono SPOT MAT'!S89/'Fisico SPOT MAT'!S89/'Fisico SPOT MAT'!E89 -> 15.598166 | R89: 1.1
A90: =YEAR(D90) -> 2025 | B90: =DATE(A90,MONTH(D90),1) -> 45992 | C90: vie | D90: =+ D89+1 -> 45996 | E90: 46.55726 | F90: =+'Mono SPOT MAT'!M90/'Fisico SPOT MAT'!M90/24 -> 41.49849 | G90: =16*R90 -> 17.6 | H90: =+'Mono ASIG'!AA90 -> 57.10996 | I90: =+H90-J90*384/744/0.52 -> 39.640978 | J90: =16*R90 -> 17.6 | N90: =+'Mono SPOT MAT'!S90/'Fisico SPOT MAT'!S90/'Fisico SPOT MAT'!E90 -> 15.745533 | R90: 1.1
A91: =YEAR(D91) -> 2025 | B91: =DATE(A91,MONTH(D91),1) -> 45992 | C91: sáb | D91: =+ D90+1 -> 45997 | E91: 59.777719 | F91: =+'Mono SPOT MAT'!M91/'Fisico SPOT MAT'!M91/24 -> 45.074175 | G91: =16*R91 -> 17.6 | H91: =+'Mono ASIG'!AA91 -> 61.338369 | I91: =+H91-J91*384/744/0.52 -> 43.869387 | J91: =16*R91 -> 17.6 | N91: =+'Mono SPOT MAT'!S91/'Fisico SPOT MAT'!S91/'Fisico SPOT MAT'!E91 -> 15.666099 | R91: 1.1
...

Sheet Fisico ASIG
B1: Mercado ASIGNADO | O1: ASIGNADA - POTENCIA
B2: Energía Generada por tipo
B3: Potencia disponible por día
F5: ENERGIA | G5: ENERGIA | H5: ENERGIA | I5: ENERGIA | J5: ENERGIA | K5: ENERGIA | L5: ENERGIA | M5: ENERGIA | N5: ENERGIA | O5: POTENCIA | P5: POTENCIA | Q5: POTENCIA | R5: POTENCIA | S5: POTENCIA | T5: POTENCIA | U5: POTENCIA | V5: POTENCIA | W5: POTENCIA
C6: VALORES FISICOS - ACUMULADO MES | F6: MW med | G6: MW med | H6: MW med | I6: MW med | J6: MW med | K6: MW med | L6: MW med | M6: MW med | N6: MW med | O6: MW disp | P6: MW disp | Q6: MW disp | R6: MW disp | S6: MW disp | T6: MW disp | U6: MW disp | V6: MW disp | W6: MW disp
D7: promedio MW/dia | E7: MES | F7: YACYRETA | G7: SALTO GRANDE | H7: HIDRO NAC Resto | I7: HIDRO COM CONCESION | J7: NUCLEAR | K7: PPA RENOV | L7: PPA TERM | M7: IMPORTACION | N7: ENER ASIG | O7: YACYRETA | P7: SALTO GRANDE | Q7: HIDRO NAC Resto | R7: HIDRO COM CONCESION | S7: NUCLEAR | T7: PPA RENOV | U7: PPA TERM | V7: IMPORTACION | W7: POT ASIG
E8: =+Precios!D8 -> 45962 | F8: =AVERAGEIFS(F$25:F$1048576,$B$25:$B$1048576,$E8) -> 2017.5955 | G8: =AVERAGEIFS(G$25:G$1048576,$B$25:$B$1048576,$E8) -> 555.64954 | H8: =AVERAGEIFS(H$25:H$1048576,$B$25:$B$1048576,$E8) -> 887.6217 | I8: =IFERROR(AVERAGEIFS(I$25:I$1048576,$B$25:$B$1048576,$E8),"-") -> - | J8: =AVERAGEIFS(J$25:J$1048576,$B$25:$B$1048576,$E8) -> 1259.5973 | K8: =AVERAGEIFS(K$25:K$1048576,$B$25:$B$1048576,$E8) -> 1752.0802 | L8: =AVERAGEIFS(L$25:L$1048576,$B$25:$B$1048576,$E8) -> 1973.3487 | M8: =AVERAGEIFS(M$25:M$1048576,$B$25:$B$1048576,$E8) -> 24.52265 | N8: =+SUM(F8:M8) -> 8470.4155 | O8: =AVERAGEIFS(O$25:O$1048576,$B$25:$B$1048576,$E8) -> 1500 | P8: =AVERAGEIFS(P$25:P$1048576,$B$25:$B$1048576,$E8) -> 842.66661 | Q8: =AVERAGEIFS(Q$25:Q$1048576,$B$25:$B$1048576,$E8) -> 5079.0934 | S8: =AVERAGEIFS(S$25:S$1048576,$B$25:$B$1048576,$E8) -> 1755 | T8: =AVERAGEIFS(T$25:T$1048576,$B$25:$B$1048576,$E8) -> 0 | U8: =AVERAGEIFS(U$25:U$1048576,$B$25:$B$1048576,$E8) -> 5296.6354 | V8: =AVERAGEIFS(V$25:V$1048576,$B$25:$B$1048576,$E8) -> 0 | W8: =+SUM(O8:V8) -> 14473.395
E9: =+Precios!D9 -> 45992 | F9: =AVERAGEIFS(F$25:F$1048576,$B$25:$B$1048576,$E9) -> 1809.1539 | G9: =AVERAGEIFS(G$25:G$1048576,$B$25:$B$1048576,$E9) -> 386.73617 | H9: =AVERAGEIFS(H$25:H$1048576,$B$25:$B$1048576,$E9) -> 814.48058 | I9: =IFERROR(AVERAGEIFS(I$25:I$1048576,$B$25:$B$1048576,$E9),"-") -> - | J9: =AVERAGEIFS(J$25:J$1048576,$B$25:$B$1048576,$E9) -> 1243.1001 | K9: =AVERAGEIFS(K$25:K$1048576,$B$25:$B$1048576,$E9) -> 1850.225 | L9: =AVERAGEIFS(L$25:L$1048576,$B$25:$B$1048576,$E9) -> 2942.6651 | M9: =AVERAGEIFS(M$25:M$1048576,$B$25:$B$1048576,$E9) -> 75.102478 | N9: =+SUM(F9:M9) -> 9121.4633 | O9: =AVERAGEIFS(O$25:O$1048576,$B$25:$B$1048576,$E9) -> 1500 | P9: =AVERAGEIFS(P$25:P$1048576,$B$25:$B$1048576,$E9) -> 892.71694 | Q9: =AVERAGEIFS(Q$25:Q$1048576,$B$25:$B$1048576,$E9) -> 5261.9461 | S9: =AVERAGEIFS(S$25:S$1048576,$B$25:$B$1048576,$E9) -> 1755 | T9: =AVERAGEIFS(T$25:T$1048576,$B$25:$B$1048576,$E9) -> 0 | U9: =AVERAGEIFS(U$25:U$1048576,$B$25:$B$1048576,$E9) -> 5727.8809 | V9: =AVERAGEIFS(V$25:V$1048576,$B$25:$B$1048576,$E9) -> 0 | W9: =+SUM(O9:V9) -> 15137.544
E10: =+Precios!D10 -> 46023 | F10: =AVERAGEIFS(F$25:F$1048576,$B$25:$B$1048576,$E10) -> 1269.4977 | G10: =AVERAGEIFS(G$25:G$1048576,$B$25:$B$1048576,$E10) -> 548.6778 | H10: =AVERAGEIFS(H$25:H$1048576,$B$25:$B$1048576,$E10) -> 353.4675 | I10: =AVERAGEIFS(I$25:I$1048576,$B$25:$B$1048576,$E10) -> 678.96589 | J10: =AVERAGEIFS(J$25:J$1048576,$B$25:$B$1048576,$E10) -> 1253.595 | K10: =AVERAGEIFS(K$25:K$1048576,$B$25:$B$1048576,$E10) -> 1731.0907 | L10: =AVERAGEIFS(L$25:L$1048576,$B$25:$B$1048576,$E10) -> 3019.2708 | M10: =AVERAGEIFS(M$25:M$1048576,$B$25:$B$1048576,$E10) -> 203.58483 | N10: =+SUM(F10:M10) -> 9058.1502 | O10: =AVERAGEIFS(O$25:O$1048576,$B$25:$B$1048576,$E10) -> 1500 | P10: =AVERAGEIFS(P$25:P$1048576,$B$25:$B$1048576,$E10) -> 922.52379 | Q10: =AVERAGEIFS(Q$25:Q$1048576,$B$25:$B$1048576,$E10) -> 2204.7347 | R10: =AVERAGEIFS(R$25:R$1048576,$B$25:$B$1048576,$E10) -> 3896.0358 | S10: =AVERAGEIFS(S$25:S$1048576,$B$25:$B$1048576,$E10) -> 1755 | T10: =AVERAGEIFS(T$25:T$1048576,$B$25:$B$1048576,$E10) -> 0 | U10: =AVERAGEIFS(U$25:U$1048576,$B$25:$B$1048576,$E10) -> 5820.8805 | V10: =AVERAGEIFS(V$25:V$1048576,$B$25:$B$1048576,$E10) -> 0 | W10: =+SUM(O10:V10) -> 16099.175
E11: =+Precios!D11 -> 46054 | F11: =AVERAGEIFS(F$25:F$1048576,$B$25:$B$1048576,$E11) -> 985.05709 | G11: =AVERAGEIFS(G$25:G$1048576,$B$25:$B$1048576,$E11) -> 245.57043 | H11: =AVERAGEIFS(H$25:H$1048576,$B$25:$B$1048576,$E11) -> 243.47859 | I11: =AVERAGEIFS(I$25:I$1048576,$B$25:$B$1048576,$E11) -> 481.37719 | J11: =AVERAGEIFS(J$25:J$1048576,$B$25:$B$1048576,$E11) -> 1234.5675 | K11: =AVERAGEIFS(K$25:K$1048576,$B$25:$B$1048576,$E11) -> 1782.9666 | L11: =AVERAGEIFS(L$25:L$1048576,$B$25:$B$1048576,$E11) -> 3090.1065 | M11: =AVERAGEIFS(M$25:M$1048576,$B$25:$B$1048576,$E11) -> 195.57906 | N11: =+SUM(F11:M11) -> 8258.7029 | O11: =AVERAGEIFS(O$25:O$1048576,$B$25:$B$1048576,$E11) -> 1500 | P11: =AVERAGEIFS(P$25:P$1048576,$B$25:$B$1048576,$E11) -> 899.3488 | Q11: =AVERAGEIFS(Q$25:Q$1048576,$B$25:$B$1048576,$E11) -> 1026.3623 | R11: =AVERAGEIFS(R$25:R$1048576,$B$25:$B$1048576,$E11) -> 3856.4639 | S11: =AVERAGEIFS(S$25:S$1048576,$B$25:$B$1048576,$E11) -> 1755 | T11: =AVERAGEIFS(T$25:T$1048576,$B$25:$B$1048576,$E11) -> 0 | U11: =AVERAGEIFS(U$25:U$1048576,$B$25:$B$1048576,$E11) -> 5825.4073 | V11: =AVERAGEIFS(V$25:V$1048576,$B$25:$B$1048576,$E11) -> 0 | W11: =+SUM(O11:V11) -> 14862.582
E12: =+Precios!D12 -> 46082 | F12: =AVERAGEIFS(F$25:F$1048576,$B$25:$B$1048576,$E12) -> 1031.0641 | G12: =AVERAGEIFS(G$25:G$1048576,$B$25:$B$1048576,$E12) -> 237.71785 | H12: =AVERAGEIFS(H$25:H$1048576,$B$25:$B$1048576,$E12) -> 247.8823 | I12: =AVERAGEIFS(I$25:I$1048576,$B$25:$B$1048576,$E12) -> 595.96721 | J12: =AVERAGEIFS(J$25:J$1048576,$B$25:$B$1048576,$E12) -> 792.34466 | K12: =AVERAGEIFS(K$25:K$1048576,$B$25:$B$1048576,$E12) -> 1740.137 | L12: =AVERAGEIFS(L$25:L$1048576,$B$25:$B$1048576,$E12) -> 3012.0061 | M12: =AVERAGEIFS(M$25:M$1048576,$B$25:$B$1048576,$E12) -> 109.93972 | N12: =+SUM(F12:M12) -> 7767.0589 | O12: =AVERAGEIFS(O$25:O$1048576,$B$25:$B$1048576,$E12) -> 1500 | P12: =AVERAGEIFS(P$25:P$1048576,$B$25:$B$1048576,$E12) -> 804.5187 | Q12: =AVERAGEIFS(Q$25:Q$1048576,$B$25:$B$1048576,$E12) -> 1006.4949 | R12: =AVERAGEIFS(R$25:R$1048576,$B$25:$B$1048576,$E12) -> 3800.676 | S12: =AVERAGEIFS(S$25:S$1048576,$B$25:$B$1048576,$E12) -> 1755 | T12: =AVERAGEIFS(T$25:T$1048576,$B$25:$B$1048576,$E12) -> 0 | U12: =AVERAGEIFS(U$25:U$1048576,$B$25:$B$1048576,$E12) -> 5369.8895 | V12: =AVERAGEIFS(V$25:V$1048576,$B$25:$B$1048576,$E12) -> 0 | W12: =+SUM(O12:V12) -> 14236.579
E13: =+Precios!D13 -> 46113 | F13: =AVERAGEIFS(F$25:F$1048576,$B$25:$B$1048576,$E13) -> 1375.4281 | G13: =AVERAGEIFS(G$25:G$1048576,$B$25:$B$1048576,$E13) -> 333.06879 | H13: =AVERAGEIFS(H$25:H$1048576,$B$25:$B$1048576,$E13) -> 250.78597 | I13: =AVERAGEIFS(I$25:I$1048576,$B$25:$B$1048576,$E13) -> 583.99947 | J13: =AVERAGEIFS(J$25:J$1048576,$B$25:$B$1048576,$E13) -> 599.63981 | K13: =AVERAGEIFS(K$25:K$1048576,$B$25:$B$1048576,$E13) -> 1634.2925 | L13: =AVERAGEIFS(L$25:L$1048576,$B$25:$B$1048576,$E13) -> 2396.1315 | M13: =AVERAGEIFS(M$25:M$1048576,$B$25:$B$1048576,$E13) -> 251.91863 | N13: =+SUM(F13:M13) -> 7425.2648 | O13: =AVERAGEIFS(O$25:O$1048576,$B$25:$B$1048576,$E13) -> 1500 | P13: =AVERAGEIFS(P$25:P$1048576,$B$25:$B$1048576,$E13) -> 827.57642 | Q13: =AVERAGEIFS(Q$25:Q$1048576,$B$25:$B$1048576,$E13) -> 969.32118 | R13: =AVERAGEIFS(R$25:R$1048576,$B$25:$B$1048576,$E13) -> 3717.7575 | S13: =AVERAGEIFS(S$25:S$1048576,$B$25:$B$1048576,$E13) -> 1755 | T13: =AVERAGEIFS(T$25:T$1048576,$B$25:$B$1048576,$E13) -> 0 | U13: =AVERAGEIFS(U$25:U$1048576,$B$25:$B$1048576,$E13) -> 5122.7089 | V13: =AVERAGEIFS(V$25:V$1048576,$B$25:$B$1048576,$E13) -> 0 | W13: =+SUM(O13:V13) -> 13892.364
E14: =+Precios!D14 -> 46143 | F14: =AVERAGEIFS(F$25:F$1048576,$B$25:$B$1048576,$E14) -> 1564.0244 | G14: =AVERAGEIFS(G$25:G$1048576,$B$25:$B$1048576,$E14) -> 451.72274 | H14: =AVERAGEIFS(H$25:H$1048576,$B$25:$B$1048576,$E14) -> 297.85809 | I14: =AVERAGEIFS(I$25:I$1048576,$B$25:$B$1048576,$E14) -> 1073.5445 | J14: =AVERAGEIFS(J$25:J$1048576,$B$25:$B$1048576,$E14) -> 1046.1918 | K14: =AVERAGEIFS(K$25:K$1048576,$B$25:$B$1048576,$E14) -> 1429.5537 | L14: =AVERAGEIFS(L$25:L$1048576,$B$25:$B$1048576,$E14) -> 2289.658 | M14: =AVERAGEIFS(M$25:M$1048576,$B$25:$B$1048576,$E14) -> 1020.0108 | N14: =+SUM(F14:M14) -> 9172.5639 | O14: =AVERAGEIFS(O$25:O$1048576,$B$25:$B$1048576,$E14) -> 1500 | P14: =AVERAGEIFS(P$25:P$1048576,$B$25:$B$1048576,$E14) -> 886.00852 | Q14: =AVERAGEIFS(Q$25:Q$1048576,$B$25:$B$1048576,$E14) -> 998.39305 | R14: =AVERAGEIFS(R$25:R$1048576,$B$25:$B$1048576,$E14) -> 3579.6586 | S14: =AVERAGEIFS(S$25:S$1048576,$B$25:$B$1048576,$E14) -> 1755 | T14: =AVERAGEIFS(T$25:T$1048576,$B$25:$B$1048576,$E14) -> 0 | U14: =AVERAGEIFS(U$25:U$1048576,$B$25:$B$1048576,$E14) -> 5148.9697 | V14: =AVERAGEIFS(V$25:V$1048576,$B$25:$B$1048576,$E14) -> 0 | W14: =+SUM(O14:V14) -> 13868.03
E15: =+Precios!D15 -> 46174 | F15: =AVERAGEIFS(F$25:F$1048576,$B$25:$B$1048576,$E15) -> 1686.7725 | G15: =AVERAGEIFS(G$25:G$1048576,$B$25:$B$1048576,$E15) -> 348.26269 | H15: =AVERAGEIFS(H$25:H$1048576,$B$25:$B$1048576,$E15) -> 260.21876 | I15: =AVERAGEIFS(I$25:I$1048576,$B$25:$B$1048576,$E15) -> 758.34585 | J15: =AVERAGEIFS(J$25:J$1048576,$B$25:$B$1048576,$E15) -> 1233.9479 | K15: =AVERAGEIFS(K$25:K$1048576,$B$25:$B$1048576,$E15) -> 1533.7654 | L15: =AVERAGEIFS(L$25:L$1048576,$B$25:$B$1048576,$E15) -> 2446.5202 | M15: =AVERAGEIFS(M$25:M$1048576,$B$25:$B$1048576,$E15) -> 1171.8153 | N15: =+SUM(F15:M15) -> 9439.6486 | O15: =AVERAGEIFS(O$25:O$1048576,$B$25:$B$1048576,$E15) -> 1500 | P15: =AVERAGEIFS(P$25:P$1048576,$B$25:$B$1048576,$E15) -> 872.24784 | Q15: =AVERAGEIFS(Q$25:Q$1048576,$B$25:$B$1048576,$E15) -> 964.06059 | R15: =AVERAGEIFS(R$25:R$1048576,$B$25:$B$1048576,$E15) -> 3616.286 | S15: =AVERAGEIFS(S$25:S$1048576,$B$25:$B$1048576,$E15) -> 1755 | T15: =AVERAGEIFS(T$25:T$1048576,$B$25:$B$1048576,$E15) -> 0 | U15: =AVERAGEIFS(U$25:U$1048576,$B$25:$B$1048576,$E15) -> 5768.451 | V15: =AVERAGEIFS(V$25:V$1048576,$B$25:$B$1048576,$E15) -> 0 | W15: =+SUM(O15:V15) -> 14476.045
E16: =+Precios!D16 -> 46204 | F16: =AVERAGEIFS(F$25:F$1048576,$B$25:$B$1048576,$E16) -> 2132.8486 | G16: =AVERAGEIFS(G$25:G$1048576,$B$25:$B$1048576,$E16) -> 840.25403 | H16: =AVERAGEIFS(H$25:H$1048576,$B$25:$B$1048576,$E16) -> 253.64798 | I16: =AVERAGEIFS(I$25:I$1048576,$B$25:$B$1048576,$E16) -> 778.4504 | J16: =AVERAGEIFS(J$25:J$1048576,$B$25:$B$1048576,$E16) -> 1306.2581 | K16: =AVERAGEIFS(K$25:K$1048576,$B$25:$B$1048576,$E16) -> 1253.179 | L16: =AVERAGEIFS(L$25:L$1048576,$B$25:$B$1048576,$E16) -> 1925.6332 | M16: =AVERAGEIFS(M$25:M$1048576,$B$25:$B$1048576,$E16) -> 1159.3605 | N16: =+SUM(F16:M16) -> 9649.6318 | O16: =AVERAGEIFS(O$25:O$1048576,$B$25:$B$1048576,$E16) -> 1500 | P16: =AVERAGEIFS(P$25:P$1048576,$B$25:$B$1048576,$E16) -> 875.50121 | Q16: =AVERAGEIFS(Q$25:Q$1048576,$B$25:$B$1048576,$E16) -> 997.64124 | R16: =AVERAGEIFS(R$25:R$1048576,$B$25:$B$1048576,$E16) -> 3603.5241 | S16: =AVERAGEIFS(S$25:S$1048576,$B$25:$B$1048576,$E16) -> 1755 | T16: =AVERAGEIFS(T$25:T$1048576,$B$25:$B$1048576,$E16) -> 0 | U16: =AVERAGEIFS(U$25:U$1048576,$B$25:$B$1048576,$E16) -> 5952.6802 | V16: =AVERAGEIFS(V$25:V$1048576,$B$25:$B$1048576,$E16) -> 0 | W16: =+SUM(O16:V16) -> 14684.347
E17: =+Precios!D17 -> 46235 | F17: =AVERAGEIFS(F$25:F$1048576,$B$25:$B$1048576,$E17) -> 2017.1744 | G17: =AVERAGEIFS(G$25:G$1048576,$B$25:$B$1048576,$E17) -> 776.2816 | H17: =AVERAGEIFS(H$25:H$1048576,$B$25:$B$1048576,$E17) -> 301.20812 | I17: =AVERAGEIFS(I$25:I$1048576,$B$25:$B$1048576,$E17) -> 1063.0158 | J17: =AVERAGEIFS(J$25:J$1048576,$B$25:$B$1048576,$E17) -> 1305.9753 | K17: =AVERAGEIFS(K$25:K$1048576,$B$25:$B$1048576,$E17) -> 1584.9492 | L17: =AVERAGEIFS(L$25:L$1048576,$B$25:$B$1048576,$E17) -> 2015.9006 | M17: =AVERAGEIFS(M$25:M$1048576,$B$25:$B$1048576,$E17) -> 1223.0406 | N17: =+SUM(F17:M17) -> 10287.546 | O17: =AVERAGEIFS(O$25:O$1048576,$B$25:$B$1048576,$E17) -> 1500 | P17: =AVERAGEIFS(P$25:P$1048576,$B$25:$B$1048576,$E17) -> 841.13132 | Q17: =AVERAGEIFS(Q$25:Q$1048576,$B$25:$B$1048576,$E17) -> 994.39424 | R17: =AVERAGEIFS(R$25:R$1048576,$B$25:$B$1048576,$E17) -> 3738.7223 | S17: =AVERAGEIFS(S$25:S$1048576,$B$25:$B$1048576,$E17) -> 1755 | T17: =AVERAGEIFS(T$25:T$1048576,$B$25:$B$1048576,$E17) -> 0 | U17: =AVERAGEIFS(U$25:U$1048576,$B$25:$B$1048576,$E17) -> 5996.1898 | V17: =AVERAGEIFS(V$25:V$1048576,$B$25:$B$1048576,$E17) -> 0 | W17: =+SUM(O17:V17) -> 14825.438
E18: =+Precios!D18 -> 46266 | F18: =AVERAGEIFS(F$25:F$1048576,$B$25:$B$1048576,$E18) -> 2256.4592 | G18: =AVERAGEIFS(G$25:G$1048576,$B$25:$B$1048576,$E18) -> 789.69389 | H18: =AVERAGEIFS(H$25:H$1048576,$B$25:$B$1048576,$E18) -> 276.37435 | I18: =AVERAGEIFS(I$25:I$1048576,$B$25:$B$1048576,$E18) -> 1062.7791 | J18: =AVERAGEIFS(J$25:J$1048576,$B$25:$B$1048576,$E18) -> 1308.8005 | K18: =AVERAGEIFS(K$25:K$1048576,$B$25:$B$1048576,$E18) -> 1756.6042 | L18: =AVERAGEIFS(L$25:L$1048576,$B$25:$B$1048576,$E18) -> 1787.6781 | M18: =AVERAGEIFS(M$25:M$1048576,$B$25:$B$1048576,$E18) -> 651.224 | N18: =+SUM(F18:M18) -> 9889.6133 | O18: =AVERAGEIFS(O$25:O$1048576,$B$25:$B$1048576,$E18) -> 1500 | P18: =AVERAGEIFS(P$25:P$1048576,$B$25:$B$1048576,$E18) -> 873.635 | Q18: =AVERAGEIFS(Q$25:Q$1048576,$B$25:$B$1048576,$E18) -> 1029.9629 | R18: =AVERAGEIFS(R$25:R$1048576,$B$25:$B$1048576,$E18) -> 3787.7661 | S18: =AVERAGEIFS(S$25:S$1048576,$B$25:$B$1048576,$E18) -> 1755 | T18: =AVERAGEIFS(T$25:T$1048576,$B$25:$B$1048576,$E18) -> 0 | U18: =AVERAGEIFS(U$25:U$1048576,$B$25:$B$1048576,$E18) -> 5616.1774 | V18: =AVERAGEIFS(V$25:V$1048576,$B$25:$B$1048576,$E18) -> 0 | W18: =+SUM(O18:V18) -> 14562.541
E19: =+Precios!D19 -> 46296 | F19: =AVERAGEIFS(F$25:F$1048576,$B$25:$B$1048576,$E19) -> 2329.52 | G19: =AVERAGEIFS(G$25:G$1048576,$B$25:$B$1048576,$E19) -> 630.92 | H19: =AVERAGEIFS(H$25:H$1048576,$B$25:$B$1048576,$E19) -> 404.28 | I19: =AVERAGEIFS(I$25:I$1048576,$B$25:$B$1048576,$E19) -> 1781.72 | J19: =AVERAGEIFS(J$25:J$1048576,$B$25:$B$1048576,$E19) -> 734.36 | K19: =AVERAGEIFS(K$25:K$1048576,$B$25:$B$1048576,$E19) -> 1572.92 | L19: =AVERAGEIFS(L$25:L$1048576,$B$25:$B$1048576,$E19) -> 1605.2 | M19: =AVERAGEIFS(M$25:M$1048576,$B$25:$B$1048576,$E19) -> 313.24 | N19: =+SUM(F19:M19) -> 9372.16 | O19: =AVERAGEIFS(O$25:O$1048576,$B$25:$B$1048576,$E19) -> 1500 | P19: =AVERAGEIFS(P$25:P$1048576,$B$25:$B$1048576,$E19) -> 687.84 | Q19: =AVERAGEIFS(Q$25:Q$1048576,$B$25:$B$1048576,$E19) -> 1012.64 | R19: =AVERAGEIFS(R$25:R$1048576,$B$25:$B$1048576,$E19) -> 3923.44 | S19: =AVERAGEIFS(S$25:S$1048576,$B$25:$B$1048576,$E19) -> 1755 | T19: =AVERAGEIFS(T$25:T$1048576,$B$25:$B$1048576,$E19) -> 0 | U19: =AVERAGEIFS(U$25:U$1048576,$B$25:$B$1048576,$E19) -> 5053.08 | V19: =AVERAGEIFS(V$25:V$1048576,$B$25:$B$1048576,$E19) -> 0 | W19: =+SUM(O19:V19) -> 13932
C22: VALORES FISICOS - PASO DIARIO | F22: ENERGIA | G22: ENERGIA | H22: ENERGIA | I22: ENERGIA | J22: ENERGIA | K22: ENERGIA | L22: ENERGIA | M22: ENERGIA | N22: ENERGIA | O22: POTENCIA | P22: POTENCIA | Q22: POTENCIA | R22: POTENCIA | S22: POTENCIA | T22: POTENCIA | U22: POTENCIA | V22: POTENCIA | W22: POTENCIA
F23: MW med | G23: MW med | H23: MW med | I23: MW med | J23: MW med | K23: MW med | L23: MW med | M23: MW med | N23: MW med | O23: MW disp | P23: MW disp | Q23: MW disp | R23: MW disp | S23: MW disp | T23: MW disp | U23: MW disp | V23: MW disp | W23: MW disp
A24: AÑO | B24: MES | C24: # dias/mes | D24: TIPO dia | E24: DIA | F24: YACYRETA | G24: SALTO GRANDE | H24: HIDRO NAC Resto | I24: HIDRO COM CONCESION | J24: NUCLEAR | K24: PPA RENOV | L24: PPA TERM | M24: IMPORTACION | N24: ENER ASIG | O24: YACYRETA | P24: SALTO GRANDE | Q24: HIDRO NAC Resto | R24: HIDRO COM CONCESION | S24: NUCLEAR | T24: PPA RENOV | U24: PPA TERM | V24: IMPORTACION | W24: POT ASIG
A25: =YEAR(E25) -> 2025 | B25: =DATE(A25,MONTH(E25),1) -> 45931 | C25: 31 | D25: mié. | E25: 45931 | F25: 1815.8247 | G25: 733.327 | H25: 754.569 | J25: 915.93338 | K25: 2226.5328 | L25: 1431.3534 | M25: 237.28671 | N25: =SUM(F25:M25) -> 8114.827 | O25: 1500 | P25: 791.63437 | Q25: 5516.6738 | S25: 1755 | T25: 0 | U25: 4819.1509 | V25: 0 | W25: =SUM(O25:V25) -> 14382.459
A26: =YEAR(E26) -> 2025 | B26: =DATE(A26,MONTH(E26),1) -> 45931 | C26: 31 | D26: jue. | E26: =+ E25+1 -> 45932 | F26: 1949.3443 | G26: 745.48846 | H26: 703.37642 | J26: 1258.4156 | K26: 2009.3687 | L26: 1408.0382 | M26: 277.71912 | N26: =SUM(F26:M26) -> 8351.7507 | O26: 1500 | P26: 808.47812 | Q26: 5504.205 | S26: 1755 | T26: 0 | U26: 4860.7804 | V26: 0 | W26: =SUM(O26:V26) -> 14428.464
A27: =YEAR(E27) -> 2025 | B27: =DATE(A27,MONTH(E27),1) -> 45931 | C27: 31 | D27: vie. | E27: =+ E26+1 -> 45933 | F27: 1939.6475 | G27: 749.67129 | H27: 961.37013 | J27: 1264.0865 | K27: 1946.2811 | L27: 1451.441 | M27: 243.12 | N27: =SUM(F27:M27) -> 8555.6174 | O27: 1500 | P27: 823.2 | Q27: 5506.8017 | S27: 1755 | T27: 0 | U27: 4945.3649 | V27: 0 | W27: =SUM(O27:V27) -> 14530.367
A28: =YEAR(E28) -> 2025 | B28: =DATE(A28,MONTH(E28),1) -> 45931 | C28: 31 | D28: sáb. | E28: =+ E27+1 -> 45934 | F28: 1438.7366 | G28: 724.03604 | H28: 941.07954 | J28: 1263.1498 | K28: 1780.7511 | L28: 1782.2303 | M28: 390.35292 | N28: =SUM(F28:M28) -> 8320.3363 | O28: 1500 | P28: 773.85 | Q28: 5526.5394 | S28: 1755 | T28: 0 | U28: 5447.4902 | V28: 0 | W28: =SUM(O28:V28) -> 15002.88
A29: =YEAR(E29) -> 2025 | B29: =DATE(A29,MONTH(E29),1) -> 45931 | C29: 31 | D29: dom. | E29: =+ E28+1 -> 45935 | F29: 1269.1058 | G29: 744.76929 | H29: 785.91979 | J29: 1262.7215 | K29: 1435.3352 | L29: 1583.318 | M29: 388.39271 | N29: =SUM(F29:M29) -> 7469.5624 | O29: 1500 | P29: 806.4 | Q29: 5529.8206 | S29: 1755 | T29: 0 | U29: 5519.7136 | V29: 0 | W29: =SUM(O29:V29) -> 15110.934
A30: =YEAR(E30) -> 2025 | B30: =DATE(A30,MONTH(E30),1) -> 45931 | C30: 31 | D30: lun. | E30: =+ E29+1 -> 45936 | F30: 1395.5035 | G30: 808.06504 | H30: 995.723 | J30: 1265.3228 | K30: 1864.646 | L30: 1753.2998 | M30: 454.37788 | N30: =SUM(F30:M30) -> 8536.938 | O30: 1500 | P30: 866.775 | Q30: 5426.6389 | S30: 1755 | T30: 0 | U30: 5682.5243 | V30: 0 | W30: =SUM(O30:V30) -> 15230.938
A31: =YEAR(E31) -> 2025 | B31: =DATE(A31,MONTH(E31),1) -> 45931 | C31: 31 | D31: mar. | E31: =+ E30+1 -> 45937 | F31: 1526.2629 | G31: 806.14721 | H31: 730.13079 | J31: 1262.5886 | K31: 1904.3338 | L31: 1640.3768 | M31: 392.88387 | N31: =SUM(F31:M31) -> 8262.724 | O31: 1500 | P31: 866.775 | Q31: 5416.7982 | S31: 1755 | T31: 0 | U31: 5766.5573 | V31: 0 | W31: =SUM(O31:V31) -> 15305.131
A32: =YEAR(E32) -> 2025 | B32: =DATE(A32,MONTH(E32),1) -> 45931 | C32: 31 | D32: mié. | E32: =+ E31+1 -> 45938 | F32: 1752.877 | G32: 789.48825 | H32: 513.77558 | J32: 1261.121 | K32: 2365.9218 | L32: 1484.0511 | M32: 231.80233 | N32: =SUM(F32:M32) -> 8399.0371 | O32: 1500 | P32: 921.375 | Q32: 5403.7869 | S32: 1755 | T32: 0 | U32: 5766.4922 | V32: 0 | W32: =SUM(O32:V32) -> 15346.654
A33: =YEAR(E33) -> 2025 | B33: =DATE(A33,MONTH(E33),1) -> 45931 | C33: 31 | D33: jue. | E33: =+ E32+1 -> 45939 | F33: 1707.2012 | G33: 786.09621 | H33: 696.89167 | J33: 1263.1178 | K33: 2157.2767 | L33: 1449.6966 | M33: 333.56487 | N33: =SUM(F33:M33) -> 8393.845 | O33: 1500 | P33: 845.25 | Q33: 5417.7331 | S33: 1755 | T33: 0 | U33: 5662.2557 | V33: 0 | W33: =SUM(O33:V33) -> 15180.239
A34: =YEAR(E34) -> 2025 | B34: =DATE(A34,MONTH(E34),1) -> 45931 | C34: 31 | D34: vie. | E34: =+ E33+1 -> 45940 | F34: 1531.6256 | G34: 797.369 | H34: 752.35717 | J34: 1261.3803 | K34: 1617.7095 | L34: 1350.1886 | M34: 392.8985 | N34: =SUM(F34:M34) -> 7703.5286 | O34: 1500 | P34: 863.1 | Q34: 5410.6675 | S34: 1755 | T34: 0 | U34: 5621.8471 | V34: 0 | W34: =SUM(O34:V34) -> 15150.615
A35: =YEAR(E35) -> 2025 | B35: =DATE(A35,MONTH(E35),1) -> 45931 | C35: 31 | D35: sáb. | E35: =+ E34+1 -> 45941 | F35: 1190.0365 | G35: 803.90588 | H35: 989.83675 | J35: 1261.7599 | K35: 1695.1419 | L35: 1465.5125 | M35: 459.20975 | N35: =SUM(F35:M35) -> 7865.4032 | O35: 1500 | P35: 863.1 | Q35: 5421.1093 | S35: 1755 | T35: 0 | U35: 5674.1109 | V35: 0 | W35: =SUM(O35:V35) -> 15213.32
A36: =YEAR(E36) -> 2025 | B36: =DATE(A36,MONTH(E36),1) -> 45931 | C36: 31 | D36: dom. | E36: =+ E35+1 -> 45942 | F36: 1351.191 | G36: 738.99133 | H36: 346.50833 | J36: 1263.5628 | K36: 2058.52 | L36: 1599.3693 | M36: 149.024 | N36: =SUM(F36:M36) -> 7507.1667 | O36: 1500 | P36: 793.275 | Q36: 5454.68 | S36: 1755 | T36: 0 | U36: 5743.3811 | V36: 0 | W36: =SUM(O36:V36) -> 15246.336
A37: =YEAR(E37) -> 2025 | B37: =DATE(A37,MONTH(E37),1) -> 45931 | C37: 31 | D37: lun. | E37: =+ E36+1 -> 45943 | F37: 2007.1348 | G37: 791.20429 | H37: 704.90517 | J37: 1262.6753 | K37: 2101.7496 | L37: 1450.4282 | M37: 391.76054 | N37: =SUM(F37:M37) -> 8709.8579 | O37: 1500 | P37: 849.45 | Q37: 5243.6318 | S37: 1755 | T37: 0 | U37: 5646.301 | V37: 0 | W37: =SUM(O37:V37) -> 14994.383
... A55: =YEAR(E55) -> 2025 | B55: =DATE(A55,MONTH(E55),1) -> 45931 | C55: 31 | D55: vie. | E55: =+ E54+1 -> 45961 | F55: 2095.6783 | G55: 657.10521 | H55: 516.52708 | J55: 1267.4595 | K55: 2283.1108 | L55: 1707.1944 | M55: 17.609167 | N55: =SUM(F55:M55) -> 8544.6844 | O55: 1500 | P55: 850.5 | Q55: 4727.6425 | S55: 1755 | T55: 0 | U55: 5142.6631 | V55: 0 | W55: =SUM(O55:V55) -> 13975.806
A56: =YEAR(E56) -> 2025 | B56: =DATE(A56,MONTH(E56),1) -> 45962 | C56: 30 | D56: sáb. | E56: 45962 | F56: 2209.085 | G56: 321.88921 | H56: 697.51738 | J56: 1266.7247 | K56: 2017.0351 | L56: 1499.8579 | M56: 13.447542 | N56: =SUM(F56:M56) -> 8025.5568 | O56: 1500 | P56: 831.075 | Q56: 4763.8894 | S56: 1755 | T56: 0 | U56: 5101.2881 | V56: 0 | W56: =+SUM(O56:V56) -> 13951.252
A57: =YEAR(E57) -> 2025 | B57: =DATE(A57,MONTH(E57),1) -> 45962 | C57: 30 | D57: dom. | E57: 45963 | F57: 1940.7099 | G57: 181.6755 | H57: 685.36642 | J57: 1268.5178 | K57: 1604.6535 | L57: 1644.6367 | M57: 12.637542 | N57: =SUM(F57:M57) -> 7338.1975 | O57: 1500 | P57: 799.575 | Q57: 4958.6863 | S57: 1755 | T57: 0 | U57: 5145.2362 | V57: 0 | W57: =+SUM(O57:V57) -> 14158.497
A58: =YEAR(E58) -> 2025 | B58: =DATE(A58,MONTH(E58),1) -> 45962 | C58: 30 | D58: lun. | E58: 45964 | F58: 2566.9223 | G58: 742.09762 | H58: 1171.6898 | J58: 1263.4837 | K58: 1371.3671 | L58: 2205.5945 | M58: 19.220458 | N58: =SUM(F58:M58) -> 9340.3756 | O58: 1500 | P58: 862.21844 | Q58: 5174.4613 | S58: 1755 | T58: 0 | U58: 5164.9815 | V58: 0 | W58: =+SUM(O58:V58) -> 14456.661
A59: =YEAR(E59) -> 2025 | B59: =DATE(A59,MONTH(E59),1) -> 45962 | C59: 30 | D59: mar. | E59: 45965 | F59: 2120.224 | G59: 804.13142 | H59: 1297.0475 | J59: 1266.0334 | K59: 1669.3403 | L59: 2117.4936 | M59: 47.099333 | N59: =SUM(F59:M59) -> 9321.3697 | O59: 1500 | P59: 884.10831 | Q59: 5172.0331 | S59: 1755 | T59: 0 | U59: 5235.2733 | V59: 0 | W59: =+SUM(O59:V59) -> 14546.415
A60: =YEAR(E60) -> 2025 | B60: =DATE(A60,MONTH(E60),1) -> 45962 | C60: 30 | D60: mié. | E60: 45966 | F60: 2221.3129 | G60: 799.9175 | H60: 990.329 | J60: 1265.661 | K60: 1646.794 | L60: 1572.1316 | M60: 57.503583 | N60: =SUM(F60:M60) -> 8553.6496 | O60: 1500 | P60: 866.55691 | Q60: 5047.6195 | S60: 1755 | T60: 0 | U60: 5238.7988 | V60: 0 | W60: =+SUM(O60:V60) -> 14407.975
...

Sheet Mono ASIG
B1: Mercado ASIGNADO | H1: $ ASIGNADA - ENERGIA $ | Q1: $ ASIGNADA - POTENCIA $ | Z1: $ ASIGNADA $
B2: PRECIOS UNITARIOS REPRESENTATIVOS
B3: Por Energía / Por Potencia
H5: VARIABLES | I5: VARIABLES | J5: VARIABLES | K5: VARIABLES | L5: VARIABLES | M5: VARIABLES | N5: VARIABLES | O5: VARIABLES | P5: VARIABLES | Q5: FIJOS | R5: FIJOS | S5: FIJOS | T5: FIJOS | U5: FIJOS | V5: FIJOS | W5: FIJOS | X5: FIJOS | Y5: FIJOS | Z5: FIJ + VAR | AA5: FIJ + VAR | AB5: FIJ + VAR | AC5: FIJ + VAR
E6: VALORES ECONOMICOS - ACUMULADO MES | H6: usd/MWh | I6: usd/MWh | J6: usd/MWh | K6: usd/MWh | L6: usd/MWh | M6: usd/MWh | N6: usd/MWh | O6: usd/MWh | P6: usd/dia | Q6: usd/MW mes | R6: usd/MW mes | S6: usd/MW mes | T6: usd/MW mes | U6: usd/MW mes | V6: usd/MW mes | W6: usd/MW mes | X6: usd/MW mes | Y6: =+P6 -> usd/dia | Z6: =+Y6 -> usd/dia | AA6: usd/Mwh | AB6: usd/Mwh | AC6: usd/Mwh
G7: MES | H7: YACYRETA | I7: SALTO GRANDE | J7: HIDRO NAC Resto | K7: HIDRO COM CONCESION | L7: NUCLEAR | M7: PPA RENOV | N7: PPA TERM | O7: IMPORTACION | P7: VAR ASIG | Q7: YACYRETA | R7: SALTO GRANDE | S7: HIDRO NAC Resto | T7: HIDRO COM CONCESION | U7: NUCLEAR | V7: PPA RENOV | W7: PPA TERM | X7: IMPORTACION | Y7: FIJOS ASIG | Z7: SUMA ASIG | AA7: MONO | AB7: POT | AC7: ENER
G8: =+'Fisico ASIG'!E8 -> 45962 | H8: =AVERAGEIFS(H$25:H$1048576,$D$25:$D$1048576,$G8) -> 28 | I8: =AVERAGEIFS(I$25:I$1048576,$D$25:$D$1048576,$G8) -> 4.7975185 | J8: =AVERAGEIFS(J$25:J$1048576,$D$25:$D$1048576,$G8) -> 5.8161641 | L8: =AVERAGEIFS(L$25:L$1048576,$D$25:$D$1048576,$G8) -> 27 | M8: =AVERAGEIFS(M$25:M$1048576,$D$25:$D$1048576,$G8) -> 71.5 | N8: =AVERAGEIFS(N$25:N$1048576,$D$25:$D$1048576,$G8) -> 38.068552 | O8: =AVERAGEIFS(O$25:O$1048576,$D$25:$D$1048576,$G8) -> 92.860415 | P8: =AVERAGEIFS(P$25:P$1048576,$D$25:$D$1048576,$G8) -> 7220427.9 | Q8: =AVERAGEIFS(Q$25:Q$1048576,$D$25:$D$1048576,$G8) -> 0 | R8: =AVERAGEIFS(R$25:R$1048576,$D$25:$D$1048576,$G8) -> 5497.7825 | S8: =AVERAGEIFS(S$25:S$1048576,$D$25:$D$1048576,$G8) -> 1540.5825 | U8: =AVERAGEIFS(U$25:U$1048576,$D$25:$D$1048576,$G8) -> 18000 | V8: =AVERAGEIFS(V$25:V$1048576,$D$25:$D$1048576,$G8) -> 0 | W8: =AVERAGEIFS(W$25:W$1048576,$D$25:$D$1048576,$G8) -> 21900 | X8: =AVERAGEIFS(X$25:X$1048576,$D$25:$D$1048576,$G8) -> 0 | Y8: =AVERAGEIFS(Y$25:Y$1048576,$D$25:$D$1048576,$G8) -> 5334795.8 | Z8: =+(P8+Y8) -> 12555224 | AA8: =+Z8/'Fisico ASIG'!N8/24 -> 61.760172 | AB8: =+$AB$21*Precios!R8*Precios!P8/Precios!W8/Precios!Q8 -> 13.384615 | AC8: =+AA8-AB8 -> 48.375557
G9: =+'Fisico ASIG'!E9 -> 45992 | H9: =AVERAGEIFS(H$25:H$1048576,$D$25:$D$1048576,$G9) -> 28 | I9: =AVERAGEIFS(I$25:I$1048576,$D$25:$D$1048576,$G9) -> 4.8642721 | J9: =AVERAGEIFS(J$25:J$1048576,$D$25:$D$1048576,$G9) -> 5.7816249 | L9: =AVERAGEIFS(L$25:L$1048576,$D$25:$D$1048576,$G9) -> 27 | M9: =AVERAGEIFS(M$25:M$1048576,$D$25:$D$1048576,$G9) -> 71.5 | N9: =AVERAGEIFS(N$25:N$1048576,$D$25:$D$1048576,$G9) -> 40.46591 | O9: =AVERAGEIFS(O$25:O$1048576,$D$25:$D$1048576,$G9) -> 104.20101 | P9: =AVERAGEIFS(P$25:P$1048576,$D$25:$D$1048576,$G9) -> 8384683.9 | Q9: =AVERAGEIFS(Q$25:Q$1048576,$D$25:$D$1048576,$G9) -> 0 | R9: =AVERAGEIFS(R$25:R$1048576,$D$25:$D$1048576,$G9) -> 5574.4373 | S9: =AVERAGEIFS(S$25:S$1048576,$D$25:$D$1048576,$G9) -> 1706.1611 | U9: =AVERAGEIFS(U$25:U$1048576,$D$25:$D$1048576,$G9) -> 18000 | V9: =AVERAGEIFS(V$25:V$1048576,$D$25:$D$1048576,$G9) -> 0 | W9: =AVERAGEIFS(W$25:W$1048576,$D$25:$D$1048576,$G9) -> 21900 | X9: =AVERAGEIFS(X$25:X$1048576,$D$25:$D$1048576,$G9) -> 0 | Y9: =AVERAGEIFS(Y$25:Y$1048576,$D$25:$D$1048576,$G9) -> 5515635.9 | Z9: =+(P9+Y9) -> 13900320 | AA9: =+Z9/'Fisico ASIG'!N9/24 -> 63.49639 | AB9: =+$AB$21*Precios!R9*Precios!P9/Precios!W9/Precios!Q9 -> 17.468983 | AC9: =+AA9-AB9 -> 46.027408
G10: =+'Fisico ASIG'!E10 -> 46023 | H10: =AVERAGEIFS(H$25:H$1048576,$D$25:$D$1048576,$G10) -> 28 | I10: =AVERAGEIFS(I$25:I$1048576,$D$25:$D$1048576,$G10) -> 5.0018454 | J10: =AVERAGEIFS(J$25:J$1048576,$D$25:$D$1048576,$G10) -> 6.5099399 | K10: =AVERAGEIFS(K$25:K$1048576,$D$25:$D$1048576,$G10) -> 7.5875 | L10: =AVERAGEIFS(L$25:L$1048576,$D$25:$D$1048576,$G10) -> 27 | M10: =AVERAGEIFS(M$25:M$1048576,$D$25:$D$1048576,$G10) -> 71.5 | N10: =AVERAGEIFS(N$25:N$1048576,$D$25:$D$1048576,$G10) -> 42.13139 | O10: =AVERAGEIFS(O$25:O$1048576,$D$25:$D$1048576,$G10) -> 80.830082 | ... Y10: =AVERAGEIFS(Y$25:Y$1048576,$D$25:$D$1048576,$G10) -> 5622846.9 | Z10: =+(P10+Y10) -> 14028881 | AA10: =+Z10/'Fisico ASIG'!N10/24 -> 64.531577 | AB10: =+$AB$21*Precios!R10*Precios!P10/Precios!W10/Precios!Q10 -> 14.996969 | AC10: =+AA10-AB10 -> 49.534608
G11: =+'Fisico ASIG'!E11 -> 46054 | H11: =AVERAGEIFS(H$25:H$1048576,$D$25:$D$1048576,$G11) -> 28 | I11: =AVERAGEIFS(I$25:I$1048576,$D$25:$D$1048576,$G11) -> 5.1392516 | J11: =AVERAGEIFS(J$25:J$1048576,$D$25:$D$1048576,$G11) -> 6.6887752 | K11: =AVERAGEIFS(K$25:K$1048576,$D$25:$D$1048576,$G11) -> 7.5875 | L11: =AVERAGEIFS(L$25:L$1048576,$D$25:$D$1048576,$G11) -> 27 | M11: =AVERAGEIFS(M$25:M$1048576,$D$25:$D$1048576,$G11) -> 71.5 | N11: =AVERAGEIFS(N$25:N$1048576,$D$25:$D$1048576,$G11) -> 41.039718 | O11: =AVERAGEIFS(O$25:O$1048576,$D$25:$D$1048576,$G11) -> 92.10906 | ... Y11: =AVERAGEIFS(Y$25:Y$1048576,$D$25:$D$1048576,$G11) -> 6227666.1 | Z11: =+(P11+Y11) -> 14495266 | AA11: =+Z11/'Fisico ASIG'!N11/24 -> 73.131269 | AB11: =+$AB$21*Precios!R11*Precios!P11/Precios!W11/Precios!Q11 -> 14.441444 | AC11: =+AA11-AB11 -> 58.689825
G12: =+'Fisico ASIG'!E12 -> 46082 | H12: =AVERAGEIFS(H$25:H$1048576,$D$25:$D$1048576,$G12) -> 28 | I12: =AVERAGEIFS(I$25:I$1048576,$D$25:$D$1048576,$G12) -> 5.2366365 | J12: =AVERAGEIFS(J$25:J$1048576,$D$25:$D$1048576,$G12) -> 5.8867926 | K12: =AVERAGEIFS(K$25:K$1048576,$D$25:$D$1048576,$G12) -> 6.8583333 | L12: =AVERAGEIFS(L$25:L$1048576,$D$25:$D$1048576,$G12) -> 27 | M12: =AVERAGEIFS(M$25:M$1048576,$D$25:$D$1048576,$G12) -> 71.5 | N12: =AVERAGEIFS(N$25:N$1048576,$D$25:$D$1048576,$G12) -> 46.488647 | O12: =AVERAGEIFS(O$25:O$1048576,$D$25:$D$1048576,$G12) -> 71.653023 | ... Y12: =AVERAGEIFS(Y$25:Y$1048576,$D$25:$D$1048576,$G12) -> 5289948.7 | Z12: =+(P12+Y12) -> 13267383 | AA12: =+Z12/'Fisico ASIG'!N12/24 -> 71.173352 | AB12: =+$AB$21*Precios!R12*Precios!P12/Precios!W12/Precios!Q12 -> 12.528037 | AC12: =+AA12-AB12 -> 58.645315
G13: =+'Fisico ASIG'!E13 -> 46113 | H13: =AVERAGEIFS(H$25:H$1048576,$D$25:$D$1048576,$G13) -> 28 | I13: =AVERAGEIFS(I$25:I$1048576,$D$25:$D$1048576,$G13) -> 5.2429398 | J13: =AVERAGEIFS(J$25:J$1048576,$D$25:$D$1048576,$G13) -> 5.8938784 | K13: =AVERAGEIFS(K$25:K$1048576,$D$25:$D$1048576,$G13) -> 6.8583333 | L13: =AVERAGEIFS(L$25:L$1048576,$D$25:$D$1048576,$G13) -> 27 | M13: =AVERAGEIFS(M$25:M$1048576,$D$25:$D$1048576,$G13) -> 71.5 | N13: =AVERAGEIFS(N$25:N$1048576,$D$25:$D$1048576,$G13) -> 52.112444 | O13: =AVERAGEIFS(O$25:O$1048576,$D$25:$D$1048576,$G13) -> 78.581543 | ... Y13: =AVERAGEIFS(Y$25:Y$1048576,$D$25:$D$1048576,$G13) -> 5276768 | Z13: =+(P13+Y13) -> 12964406 | AA13: =+Z13/'Fisico ASIG'!N13/24 -> 72.749403 | AB13: =+$AB$21*Precios!R13*Precios!P13/Precios!W13/Precios!Q13 -> 12.966822 | AC13: =+AA13-AB13 -> 59.782581
G14: =+'Fisico ASIG'!E14 -> 46143 | H14: =AVERAGEIFS(H$25:H$1048576,$D$25:$D$1048576,$G14) -> 28 | I14: =AVERAGEIFS(I$25:I$1048576,$D$25:$D$1048576,$G14) -> 5.1344035 | J14: =AVERAGEIFS(J$25:J$1048576,$D$25:$D$1048576,$G14) -> 5.7718668 | K14: =AVERAGEIFS(K$25:K$1048576,$D$25:$D$1048576,$G14) -> 6.8583333 | L14: =AVERAGEIFS(L$25:L$1048576,$D$25:$D$1048576,$G14) -> 27 | M14: =AVERAGEIFS(M$25:M$1048576,$D$25:$D$1048576,$G14) -> 71.5 | N14: =AVERAGEIFS(N$25:N$1048576,$D$25:$D$1048576,$G14) -> 99.970133 | O14: =AVERAGEIFS(O$25:O$1048576,$D$25:$D$1048576,$G14) -> 146.77674 | ... Y14: =AVERAGEIFS(Y$25:Y$1048576,$D$25:$D$1048576,$G14) -> 5125677.5 | Z14: =+(P14+Y14) -> 18830398 | AA14: =+Z14/'Fisico ASIG'!N14/24 -> 85.537689 | AB14: =+$AB$21*Precios!R14*Precios!P14/Precios!W14/Precios!Q14 -> 11.157385 | AC14: =+AA14-AB14 -> 74.380304
G15: =+'Fisico ASIG'!E15 -> 46174 | H15: =AVERAGEIFS(H$25:H$1048576,$D$25:$D$1048576,$G15) -> 28 | I15: =AVERAGEIFS(I$25:I$1048576,$D$25:$D$1048576,$G15) -> 4.8826051 | J15: =AVERAGEIFS(J$25:J$1048576,$D$25:$D$1048576,$G15) -> 5.4888062 | K15: =AVERAGEIFS(K$25:K$1048576,$D$25:$D$1048576,$G15) -> 6.8583333 | L15: =AVERAGEIFS(L$25:L$1048576,$D$25:$D$1048576,$G15) -> 27 | M15: =AVERAGEIFS(M$25:M$1048576,$D$25:$D$1048576,$G15) -> 71.5 | N15: =AVERAGEIFS(N$25:N$1048576,$D$25:$D$1048576,$G15) -> 120.01523 | O15: =AVERAGEIFS(O$25:O$1048576,$D$25:$D$1048576,$G15) -> 159.31814 | ... Y15: =AVERAGEIFS(Y$25:Y$1048576,$D$25:$D$1048576,$G15) -> 5731949.7 | Z15: =+(P15+Y15) -> 21996385 | AA15: =+Z15/'Fisico ASIG'!N15/24 -> 97.092179 | AB15: =+$AB$21*Precios!R15*Precios!P15/Precios!W15/Precios!Q15 -> 13.786852 | AC15: =+AA15-AB15 -> 83.305327
G16: =+'Fisico ASIG'!E16 -> 46204 | H16: =AVERAGEIFS(H$25:H$1048576,$D$25:$D$1048576,$G16) -> 28 | I16: =AVERAGEIFS(I$25:I$1048576,$D$25:$D$1048576,$G16) -> 4.8647821 | J16: =AVERAGEIFS(J$25:J$1048576,$D$25:$D$1048576,$G16) -> 5.4687705 | K16: =AVERAGEIFS(K$25:K$1048576,$D$25:$D$1048576,$G16) -> 6.8583333 | L16: =AVERAGEIFS(L$25:L$1048576,$D$25:$D$1048576,$G16) -> 27 | M16: =AVERAGEIFS(M$25:M$1048576,$D$25:$D$1048576,$G16) -> 71.5 | N16: =AVERAGEIFS(N$25:N$1048576,$D$25:$D$1048576,$G16) -> 104.78892 | O16: =AVERAGEIFS(O$25:O$1048576,$D$25:$D$1048576,$G16) -> 104.28886 | ... Y16: =AVERAGEIFS(Y$25:Y$1048576,$D$25:$D$1048576,$G16) -> 5679138.2 | Z16: =+(P16+Y16) -> 18427369 | AA16: =+Z16/'Fisico ASIG'!N16/24 -> 79.568531 | AB16: =+$AB$21*Precios!R16*Precios!P16/Precios!W16/Precios!Q16 -> 14.137513 | AC16: =+AA16-AB16 -> 65.431018
